[INFO] 2025-10-06 00:03:08,976 django.utils.autoreload Watching for file changes with StatReloader
[INFO] 2025-10-06 00:05:53,644 django.utils.autoreload C:\Users\2001k\OneDrive\Desktop\Auto_Care\auto_care_backend\apps\accounts\api\serializers.py changed, reloading.
[INFO] 2025-10-06 00:05:55,508 django.utils.autoreload Watching for file changes with StatReloader
[INFO] 2025-10-06 00:06:14,165 django.utils.autoreload C:\Users\2001k\OneDrive\Desktop\Auto_Care\auto_care_backend\apps\accounts\api\serializers.py changed, reloading.
[INFO] 2025-10-06 00:06:15,483 django.utils.autoreload Watching for file changes with StatReloader
[INFO] 2025-10-06 00:06:39,132 django.utils.autoreload C:\Users\2001k\OneDrive\Desktop\Auto_Care\auto_care_backend\apps\accounts\api\serializers.py changed, reloading.
[INFO] 2025-10-06 00:06:40,337 django.utils.autoreload Watching for file changes with StatReloader
[INFO] 2025-10-06 00:06:49,941 django.utils.autoreload C:\Users\2001k\OneDrive\Desktop\Auto_Care\auto_care_backend\apps\accounts\api\serializers.py changed, reloading.
[INFO] 2025-10-06 00:06:51,477 django.utils.autoreload Watching for file changes with StatReloader
[INFO] 2025-10-06 00:07:11,039 django.utils.autoreload Watching for file changes with StatReloader
[INFO] 2025-10-06 00:08:23,873 django.utils.autoreload C:\Users\2001k\OneDrive\Desktop\Auto_Care\auto_care_backend\apps\accounts\api\serializers.py changed, reloading.
[INFO] 2025-10-06 00:08:25,360 django.utils.autoreload Watching for file changes with StatReloader
[INFO] 2025-10-06 00:10:45,232 django.utils.autoreload C:\Users\2001k\OneDrive\Desktop\Auto_Care\auto_care_backend\apps\accounts\api\serializers.py changed, reloading.
[INFO] 2025-10-06 00:10:46,593 django.utils.autoreload Watching for file changes with StatReloader
[INFO] 2025-10-06 00:10:54,780 django.utils.autoreload Watching for file changes with StatReloader
[INFO] 2025-10-06 00:11:57,406 django.utils.autoreload C:\Users\2001k\OneDrive\Desktop\Auto_Care\auto_care_backend\apps\accounts\api\serializers.py changed, reloading.
[INFO] 2025-10-06 00:11:59,119 django.utils.autoreload Watching for file changes with StatReloader
[INFO] 2025-10-06 00:12:01,885 django.utils.autoreload C:\Users\2001k\OneDrive\Desktop\Auto_Care\auto_care_backend\apps\accounts\api\serializers.py changed, reloading.
[INFO] 2025-10-06 00:12:03,590 django.utils.autoreload Watching for file changes with StatReloader
[INFO] 2025-10-06 00:12:17,709 django.utils.autoreload C:\Users\2001k\OneDrive\Desktop\Auto_Care\auto_care_backend\apps\accounts\api\serializers.py changed, reloading.
[INFO] 2025-10-06 00:12:19,018 django.utils.autoreload Watching for file changes with StatReloader
[INFO] 2025-10-06 00:12:38,974 django.utils.autoreload C:\Users\2001k\OneDrive\Desktop\Auto_Care\auto_care_backend\apps\accounts\api\serializers.py changed, reloading.
[INFO] 2025-10-06 00:12:40,525 django.utils.autoreload Watching for file changes with StatReloader
[INFO] 2025-10-06 00:12:43,582 django.utils.autoreload C:\Users\2001k\OneDrive\Desktop\Auto_Care\auto_care_backend\apps\accounts\api\serializers.py changed, reloading.
[INFO] 2025-10-06 00:12:44,820 django.utils.autoreload Watching for file changes with StatReloader
[INFO] 2025-10-06 00:13:26,363 django.utils.autoreload Watching for file changes with StatReloader
[INFO] 2025-10-06 00:18:09,302 django.utils.autoreload C:\Users\2001k\OneDrive\Desktop\Auto_Care\auto_care_backend\apps\accounts\api\serializers.py changed, reloading.
[INFO] 2025-10-06 00:18:11,184 django.utils.autoreload Watching for file changes with StatReloader
[INFO] 2025-10-06 00:18:18,833 django.utils.autoreload Watching for file changes with StatReloader
[INFO] 2025-10-06 00:19:45,351 django.utils.autoreload C:\Users\2001k\OneDrive\Desktop\Auto_Care\auto_care_backend\apps\accounts\api\serializers.py changed, reloading.
[INFO] 2025-10-06 00:19:47,086 django.utils.autoreload Watching for file changes with StatReloader
[INFO] 2025-10-06 00:19:53,365 django.utils.autoreload C:\Users\2001k\OneDrive\Desktop\Auto_Care\auto_care_backend\apps\accounts\api\serializers.py changed, reloading.
[INFO] 2025-10-06 00:19:54,994 django.utils.autoreload Watching for file changes with StatReloader
[INFO] 2025-10-06 00:19:58,258 django.utils.autoreload C:\Users\2001k\OneDrive\Desktop\Auto_Care\auto_care_backend\apps\accounts\api\serializers.py changed, reloading.
[INFO] 2025-10-06 00:19:59,457 django.utils.autoreload Watching for file changes with StatReloader
[INFO] 2025-10-06 00:20:05,239 django.utils.autoreload Watching for file changes with StatReloader
[INFO] 2025-10-06 00:23:09,584 django.utils.autoreload Watching for file changes with StatReloader
[WARNING] 2025-10-06 00:23:30,248 django.request Not Found: /
[WARNING] 2025-10-06 00:23:30,250 django.server "GET / HTTP/1.1" 404 2472
[WARNING] 2025-10-06 00:23:31,217 django.request Not Found: /favicon.ico
[WARNING] 2025-10-06 00:23:31,220 django.server "GET /favicon.ico HTTP/1.1" 404 2523
[INFO] 2025-10-06 00:24:06,859 django.server "GET /admin HTTP/1.1" 301 0
[INFO] 2025-10-06 00:24:06,892 django.server "GET /admin/ HTTP/1.1" 302 0
[INFO] 2025-10-06 00:24:07,055 django.server "GET /admin/login/?next=/admin/ HTTP/1.1" 200 4177
[INFO] 2025-10-06 00:24:07,510 django.server "GET /static/admin/css/base.css HTTP/1.1" 200 22120
[INFO] 2025-10-06 00:24:07,557 django.server "GET /static/admin/css/nav_sidebar.css HTTP/1.1" 200 2810
[INFO] 2025-10-06 00:24:07,592 django.server "GET /static/admin/css/dark_mode.css HTTP/1.1" 200 2808
[INFO] 2025-10-06 00:24:07,604 django.server "GET /static/admin/css/login.css HTTP/1.1" 200 951
[INFO] 2025-10-06 00:24:07,612 django.server "GET /static/admin/css/responsive.css HTTP/1.1" 200 16565
[INFO] 2025-10-06 00:24:07,616 django.server "GET /static/admin/js/theme.js HTTP/1.1" 200 1653
[INFO] 2025-10-06 00:24:07,624 django.server "GET /static/admin/js/nav_sidebar.js HTTP/1.1" 200 3063
[INFO] 2025-10-06 00:24:21,033 django.server "POST /admin/login/?next=/admin/ HTTP/1.1" 302 0
[INFO] 2025-10-06 00:24:21,135 django.server "GET /admin/ HTTP/1.1" 200 9972
[INFO] 2025-10-06 00:24:21,195 django.server "GET /static/admin/css/dashboard.css HTTP/1.1" 200 441
[INFO] 2025-10-06 00:24:21,238 django.server "GET /static/admin/img/icon-changelink.svg HTTP/1.1" 200 380
[INFO] 2025-10-06 00:24:21,238 django.server "GET /static/admin/img/icon-addlink.svg HTTP/1.1" 200 331
[INFO] 2025-10-06 21:39:47,499 django.utils.autoreload Watching for file changes with StatReloader
[WARNING] 2025-10-06 21:39:51,730 django.request Not Found: /
[WARNING] 2025-10-06 21:39:51,735 django.server "GET / HTTP/1.1" 404 2472
[WARNING] 2025-10-06 21:39:53,125 django.request Not Found: /favicon.ico
[WARNING] 2025-10-06 21:39:53,127 django.server "GET /favicon.ico HTTP/1.1" 404 2523
[INFO] 2025-10-06 21:39:57,729 django.server "GET /admin HTTP/1.1" 301 0
[INFO] 2025-10-06 21:39:57,939 django.server "GET /admin/ HTTP/1.1" 200 9972
[INFO] 2025-10-06 21:39:58,414 django.server "GET /static/admin/css/base.css HTTP/1.1" 200 22120
[INFO] 2025-10-06 21:39:58,441 django.server "GET /static/admin/css/dark_mode.css HTTP/1.1" 200 2808
[INFO] 2025-10-06 21:39:58,444 django.server "GET /static/admin/css/nav_sidebar.css HTTP/1.1" 200 2810
[INFO] 2025-10-06 21:39:58,448 django.server "GET /static/admin/js/theme.js HTTP/1.1" 200 1653
[INFO] 2025-10-06 21:39:58,460 django.server "GET /static/admin/css/dashboard.css HTTP/1.1" 200 441
[INFO] 2025-10-06 21:39:58,465 django.server "GET /static/admin/js/nav_sidebar.js HTTP/1.1" 200 3063
[INFO] 2025-10-06 21:39:58,467 django.server "GET /static/admin/css/responsive.css HTTP/1.1" 200 16565
[INFO] 2025-10-06 21:39:58,484 django.server "GET /static/admin/img/icon-changelink.svg HTTP/1.1" 200 380
[INFO] 2025-10-06 21:39:58,491 django.server "GET /static/admin/img/icon-addlink.svg HTTP/1.1" 200 331
[INFO] 2025-10-06 21:40:04,358 django.server "GET /admin/accounts/user/add/ HTTP/1.1" 200 14563
[INFO] 2025-10-06 21:40:04,430 django.server "GET /static/admin/css/forms.css HTTP/1.1" 200 8525
[INFO] 2025-10-06 21:40:04,465 django.server "GET /static/admin/js/admin/RelatedObjectLookups.js HTTP/1.1" 200 9777
[INFO] 2025-10-06 21:40:04,483 django.server "GET /static/admin/js/jquery.init.js HTTP/1.1" 200 347
[INFO] 2025-10-06 21:40:04,501 django.server "GET /static/admin/js/core.js HTTP/1.1" 200 6208
[INFO] 2025-10-06 21:40:04,511 django.server "GET /static/admin/css/widgets.css HTTP/1.1" 200 11991
[INFO] 2025-10-06 21:40:04,512 django.server "GET /static/admin/js/actions.js HTTP/1.1" 200 8076
[INFO] 2025-10-06 21:40:04,515 django.server "GET /static/admin/css/unusable_password_field.css HTTP/1.1" 200 663
[INFO] 2025-10-06 21:40:04,516 django.server "GET /static/admin/js/vendor/jquery/jquery.js HTTP/1.1" 200 285314
[INFO] 2025-10-06 21:40:04,533 django.server "GET /static/admin/js/urlify.js HTTP/1.1" 200 7887
[INFO] 2025-10-06 21:40:04,538 django.server "GET /static/admin/js/prepopulate.js HTTP/1.1" 200 1531
[INFO] 2025-10-06 21:40:04,559 django.server "GET /static/admin/js/prepopulate_init.js HTTP/1.1" 200 586
[INFO] 2025-10-06 21:40:04,591 django.server "GET /static/admin/js/vendor/xregexp/xregexp.js HTTP/1.1" 200 325171
[INFO] 2025-10-06 21:40:04,600 django.server "GET /static/admin/js/change_form.js HTTP/1.1" 200 606
[INFO] 2025-10-06 21:40:04,614 django.server "GET /static/admin/js/unusable_password_field.js HTTP/1.1" 200 1480
[INFO] 2025-10-06 21:40:04,661 django.server "GET /admin/jsi18n/ HTTP/1.1" 200 3342
[INFO] 2025-10-06 21:40:11,906 django.server "GET /admin/accounts/user/ HTTP/1.1" 200 13882
[INFO] 2025-10-06 21:40:11,940 django.server "GET /static/admin/css/changelists.css HTTP/1.1" 200 6878
[INFO] 2025-10-06 21:40:11,961 django.server "GET /static/admin/img/icon-yes.svg HTTP/1.1" 200 436
[INFO] 2025-10-06 21:40:11,965 django.server "GET /static/admin/img/search.svg HTTP/1.1" 200 458
[INFO] 2025-10-06 21:40:11,979 django.server "GET /static/admin/js/filters.js HTTP/1.1" 200 978
[INFO] 2025-10-06 21:40:12,092 django.server "GET /admin/jsi18n/ HTTP/1.1" 200 3342
[INFO] 2025-10-06 21:40:12,254 django.server "GET /static/admin/img/tooltag-add.svg HTTP/1.1" 200 331
[INFO] 2025-10-06 21:40:12,259 django.server "GET /static/admin/img/icon-viewlink.svg HTTP/1.1" 200 581
[INFO] 2025-10-06 21:40:14,378 django.server "GET /admin/accounts/user/?_facets=True HTTP/1.1" 200 14205
[INFO] 2025-10-06 21:40:14,601 django.server "GET /admin/jsi18n/ HTTP/1.1" 200 3342
[INFO] 2025-10-06 21:40:14,736 django.server "GET /static/admin/img/icon-hidelink.svg HTTP/1.1" 200 784
[INFO] 2025-10-06 21:40:19,138 django.server "GET /admin/accounts/user/1/change/?_changelist_filters=_facets%3DTrue HTTP/1.1" 200 23463
[INFO] 2025-10-06 21:40:19,198 django.server "GET /static/admin/js/SelectBox.js HTTP/1.1" 200 4530
[INFO] 2025-10-06 21:40:19,198 django.server "GET /static/admin/js/SelectFilter2.js HTTP/1.1" 200 15845
[INFO] 2025-10-06 21:40:19,340 django.server "GET /admin/jsi18n/ HTTP/1.1" 200 3342
[INFO] 2025-10-06 21:40:19,828 django.server "GET /static/admin/img/selector-icons.svg HTTP/1.1" 200 3291
[INFO] 2025-10-06 21:41:14,056 django.utils.autoreload Watching for file changes with StatReloader
[INFO] 2025-10-06 21:41:19,200 apps.accounts.api.views OTP request received from IP: 127.0.0.1
[INFO] 2025-10-06 21:41:19,372 apps.accounts.api.views New user created: 8999513014
[INFO] 2025-10-06 21:41:19,377 apps.accounts.api.views OTP generated for 8999513014: 717652
[INFO] 2025-10-06 21:41:19,380 django.server "POST /api/accounts/send-otp/ HTTP/1.1" 200 64
[WARNING] 2025-10-06 21:42:05,376 apps.accounts.api.views No valid OTP found for 9112666031
[WARNING] 2025-10-06 21:42:05,378 django.request Bad Request: /api/accounts/verify-otp/
[WARNING] 2025-10-06 21:42:05,379 django.server "POST /api/accounts/verify-otp/ HTTP/1.1" 400 61
[INFO] 2025-10-06 21:42:17,547 apps.accounts.api.views Successful login for 8999513014 (New user: False)
[INFO] 2025-10-06 21:42:17,549 django.server "POST /api/accounts/verify-otp/ HTTP/1.1" 200 570
[WARNING] 2025-10-06 21:44:15,559 django.request Not Found: /api/profile/
[WARNING] 2025-10-06 21:44:15,562 django.server "GET /api/profile/ HTTP/1.1" 404 2526
[WARNING] 2025-10-06 21:44:26,083 django.request Not Found: /api/profile/
[WARNING] 2025-10-06 21:44:26,084 django.server "GET /api/profile/ HTTP/1.1" 404 2526
[WARNING] 2025-10-06 21:44:39,680 django.request Not Found: /api/profile/
[WARNING] 2025-10-06 21:44:39,702 django.server "GET /api/profile/ HTTP/1.1" 404 2526
[WARNING] 2025-10-06 21:45:08,475 django.request Not Found: /api/profile/8999513014
[WARNING] 2025-10-06 21:45:08,476 django.server "GET /api/profile/8999513014 HTTP/1.1" 404 2556
[WARNING] 2025-10-06 21:45:14,759 django.request Not Found: /api/profile/8999513014
[WARNING] 2025-10-06 21:45:14,760 django.server "GET /api/profile/8999513014 HTTP/1.1" 404 2556
[WARNING] 2025-10-06 21:46:54,222 django.request Not Found: /api/profile/8999513014
[WARNING] 2025-10-06 21:46:54,223 django.server "GET /api/profile/8999513014 HTTP/1.1" 404 2556
[WARNING] 2025-10-06 21:47:12,873 django.request Not Found: /api/profile/8999513014/
[WARNING] 2025-10-06 21:47:12,873 django.server "GET /api/profile/8999513014/ HTTP/1.1" 404 2559
[WARNING] 2025-10-06 21:47:34,869 django.request Not Found: /api/accounts/profile/8999513014/
[WARNING] 2025-10-06 21:47:34,871 django.server "GET /api/accounts/profile/8999513014/ HTTP/1.1" 404 3530
[WARNING] 2025-10-06 21:47:38,610 django.request Not Found: /api/accounts/profile/8999513014
[WARNING] 2025-10-06 21:47:38,611 django.server "GET /api/accounts/profile/8999513014 HTTP/1.1" 404 3527
[WARNING] 2025-10-06 21:47:44,155 django.request Unauthorized: /api/accounts/profile/
[WARNING] 2025-10-06 21:47:44,156 django.server "GET /api/accounts/profile/ HTTP/1.1" 401 107
[WARNING] 2025-10-06 21:48:33,660 django.request Unauthorized: /api/accounts/profile/
[WARNING] 2025-10-06 21:48:33,662 django.server "GET /api/accounts/profile/ HTTP/1.1" 401 107
[WARNING] 2025-10-06 21:48:41,020 django.request Not Found: /api/accounts/profile/8999513014
[WARNING] 2025-10-06 21:48:41,021 django.server "GET /api/accounts/profile/8999513014 HTTP/1.1" 404 3527
[WARNING] 2025-10-06 21:48:42,555 django.request Not Found: /api/accounts/profile/8999513014
[WARNING] 2025-10-06 21:48:42,556 django.server "GET /api/accounts/profile/8999513014 HTTP/1.1" 404 3527
[WARNING] 2025-10-06 21:48:56,800 django.request Not Found: /api/accounts/profile/8999513014
[WARNING] 2025-10-06 21:48:56,800 django.server "GET /api/accounts/profile/8999513014 HTTP/1.1" 404 3527
[WARNING] 2025-10-06 23:43:30,553 apps.accounts.api.views No valid OTP found for 8999513014
[WARNING] 2025-10-06 23:43:30,574 django.request Bad Request: /api/accounts/verify-otp/
[WARNING] 2025-10-06 23:43:30,578 django.server "POST /api/accounts/verify-otp/ HTTP/1.1" 400 61
[INFO] 2025-10-06 23:43:35,895 apps.accounts.api.views OTP request received from IP: 127.0.0.1
[INFO] 2025-10-06 23:43:36,032 apps.accounts.api.views OTP generated for 8999513014: 585688
[INFO] 2025-10-06 23:43:36,039 django.server "POST /api/accounts/send-otp/ HTTP/1.1" 200 64
[INFO] 2025-10-06 23:43:56,758 apps.accounts.api.views Successful login for 8999513014 (New user: False)
[INFO] 2025-10-06 23:43:56,760 django.server "POST /api/accounts/verify-otp/ HTTP/1.1" 200 570
[WARNING] 2025-10-06 23:44:29,937 django.request Unauthorized: /api/accounts/profile/
[WARNING] 2025-10-06 23:44:29,938 django.server "GET /api/accounts/profile/ HTTP/1.1" 401 107
[WARNING] 2025-10-06 23:44:55,145 django.request Unauthorized: /api/accounts/profile/
[WARNING] 2025-10-06 23:44:55,153 django.server "GET /api/accounts/profile/ HTTP/1.1" 401 107
[INFO] 2025-10-06 23:45:13,075 apps.accounts.api.views Profile fetched for 8999513014
[INFO] 2025-10-06 23:45:13,117 django.server "GET /api/accounts/profile/ HTTP/1.1" 200 60
[INFO] 2025-10-06 23:47:00,879 apps.accounts.api.views Profile updated for 8999513014
[INFO] 2025-10-06 23:47:00,881 django.server "PUT /api/accounts/profile/ HTTP/1.1" 200 82
[INFO] 2025-10-06 23:48:41,576 apps.bookings.api.views Booking created: 1 for user 8999513014
[INFO] 2025-10-06 23:48:41,627 django.server "POST /api/bookings/ HTTP/1.1" 201 175
[INFO] 2025-10-06 23:50:04,981 apps.bookings.api.views Booking created: 2 for user 8999513014
[INFO] 2025-10-06 23:50:04,983 django.server "POST /api/bookings/ HTTP/1.1" 201 150
[INFO] 2025-10-06 23:50:18,089 apps.bookings.api.views Bookings listed for user 8999513014: 2 bookings
[INFO] 2025-10-06 23:50:18,094 django.server "GET /api/bookings/ HTTP/1.1" 200 328
[INFO] 2025-10-06 23:50:32,774 apps.bookings.api.views Bookings listed for user 8999513014: 2 bookings
[INFO] 2025-10-06 23:50:32,781 django.server "GET /api/bookings/ HTTP/1.1" 200 328
[INFO] 2025-10-06 23:51:15,184 django.server "GET /admin/ HTTP/1.1" 302 0
[INFO] 2025-10-06 23:51:15,284 django.server "GET /admin/login/?next=/admin/ HTTP/1.1" 200 4177
[WARNING] 2025-10-06 23:51:21,772 django.security.csrf Forbidden (CSRF token missing.): /admin/
[WARNING] 2025-10-06 23:51:21,774 django.server "POST /admin/ HTTP/1.1" 403 2491
[INFO] 2025-10-07 00:07:46,214 apps.bookings.api.views Bookings listed for user 8999513014: 2 bookings
[INFO] 2025-10-07 00:07:46,225 django.server "GET /api/bookings/ HTTP/1.1" 200 328
[INFO] 2025-10-08 21:36:55,345 django.utils.autoreload Watching for file changes with StatReloader
[INFO] 2025-10-08 21:39:42,405 apps.accounts.api.views OTP request received from IP: 127.0.0.1
[INFO] 2025-10-08 21:39:42,677 apps.accounts.api.views OTP generated for 9168238418: 528183
[INFO] 2025-10-08 21:39:42,690 django.server "POST /api/accounts/send-otp/ HTTP/1.1" 200 64
[WARNING] 2025-10-08 21:40:14,386 apps.accounts.api.views Invalid OTP attempt for 9168238418. Remaining: 2
[WARNING] 2025-10-08 21:40:14,426 django.request Bad Request: /api/accounts/verify-otp/
[WARNING] 2025-10-08 21:40:14,452 django.server "POST /api/accounts/verify-otp/ HTTP/1.1" 400 48
[INFO] 2025-10-08 21:40:25,900 apps.accounts.api.views Successful login for 9168238418 (New user: False)
[INFO] 2025-10-08 21:40:25,901 django.server "POST /api/accounts/verify-otp/ HTTP/1.1" 200 570
[INFO] 2025-10-08 22:26:22,252 django.utils.autoreload Watching for file changes with StatReloader
[INFO] 2025-10-08 22:44:21,937 django.utils.autoreload Watching for file changes with StatReloader
[INFO] 2025-10-09 00:31:44,582 django.utils.autoreload Watching for file changes with StatReloader
[INFO] 2025-10-09 09:09:32,579 django.utils.autoreload Watching for file changes with StatReloader
[INFO] 2025-10-09 09:24:08,988 django.utils.autoreload Watching for file changes with StatReloader
[INFO] 2025-10-09 09:34:28,743 django.utils.autoreload Watching for file changes with StatReloader
[INFO] 2025-10-09 09:45:56,500 django.utils.autoreload Watching for file changes with StatReloader
[INFO] 2025-10-09 09:48:23,500 django.utils.autoreload C:\Users\2001k\OneDrive\Desktop\Auto_Care\auto_care_backend\auto_care\settings.py changed, reloading.
[INFO] 2025-10-09 09:49:02,715 django.utils.autoreload Watching for file changes with StatReloader
[INFO] 2025-10-09 09:49:44,957 django.server "GET /admin/ HTTP/1.1" 200 9972
[INFO] 2025-10-09 09:49:45,466 django.server "GET /static/admin/css/base.css HTTP/1.1" 200 22120
[INFO] 2025-10-09 09:49:45,485 django.server "GET /static/admin/css/dark_mode.css HTTP/1.1" 200 2808
[INFO] 2025-10-09 09:49:45,527 django.server "GET /static/admin/css/nav_sidebar.css HTTP/1.1" 200 2810
[INFO] 2025-10-09 09:49:45,528 django.server "GET /static/admin/css/dashboard.css HTTP/1.1" 200 441
[INFO] 2025-10-09 09:49:45,533 django.server "GET /static/admin/css/responsive.css HTTP/1.1" 200 16565
[INFO] 2025-10-09 09:49:45,539 django.server "GET /static/admin/js/theme.js HTTP/1.1" 200 1653
[INFO] 2025-10-09 09:49:45,547 django.server "GET /static/admin/js/nav_sidebar.js HTTP/1.1" 200 3063
[INFO] 2025-10-09 09:49:45,565 django.server "GET /static/admin/img/icon-addlink.svg HTTP/1.1" 200 331
[INFO] 2025-10-09 09:49:45,565 django.server "GET /static/admin/img/icon-changelink.svg HTTP/1.1" 200 380
[WARNING] 2025-10-09 09:49:45,734 django.request Not Found: /favicon.ico
[WARNING] 2025-10-09 09:49:45,735 django.server "GET /favicon.ico HTTP/1.1" 404 2523
[INFO] 2025-10-09 10:04:53,039 django.utils.autoreload Watching for file changes with StatReloader
[INFO] 2025-10-09 10:06:53,458 django.server "GET /admin/ HTTP/1.1" 200 9972
[INFO] 2025-10-09 10:10:29,107 django.utils.autoreload Watching for file changes with StatReloader
[INFO] 2025-10-09 10:15:03,676 django.utils.autoreload Watching for file changes with StatReloader
[INFO] 2025-10-09 10:16:13,294 django.server "OPTIONS /api/accounts/send-otp/ HTTP/1.1" 200 0
[INFO] 2025-10-09 10:16:13,319 apps.accounts.api.views OTP request received from IP: 10.240.95.214
[INFO] 2025-10-09 10:16:13,557 apps.accounts.api.views New user created: 9112666031
[INFO] 2025-10-09 10:16:13,568 apps.accounts.api.views OTP generated for 9112666031: 080165
[INFO] 2025-10-09 10:16:13,575 django.server "POST /api/accounts/send-otp/ HTTP/1.1" 200 64
[INFO] 2025-10-09 10:16:32,974 django.server "OPTIONS /api/accounts/verify-otp/ HTTP/1.1" 200 0
[INFO] 2025-10-09 10:16:33,263 apps.accounts.api.views Successful login for 9112666031 (New user: False)
[INFO] 2025-10-09 10:16:33,265 django.server "POST /api/accounts/verify-otp/ HTTP/1.1" 200 570
[INFO] 2025-10-09 10:18:10,502 django.server "OPTIONS /api/bookings/ HTTP/1.1" 200 0
[INFO] 2025-10-09 10:18:10,606 apps.bookings.api.views Booking created: 3 for user 9112666031
[INFO] 2025-10-09 10:18:10,620 django.server "POST /api/bookings/ HTTP/1.1" 201 157
[INFO] 2025-10-09 10:39:01,030 django.utils.autoreload Watching for file changes with StatReloader
[INFO] 2025-10-09 10:40:03,496 django.server "OPTIONS /api/accounts/send-otp/ HTTP/1.1" 200 0
[INFO] 2025-10-09 10:40:03,535 apps.accounts.api.views OTP request received from IP: 10.240.95.214
[INFO] 2025-10-09 10:40:03,723 apps.accounts.api.views OTP generated for 9168238418: 985665
[INFO] 2025-10-09 10:40:03,725 django.server "POST /api/accounts/send-otp/ HTTP/1.1" 200 64
[INFO] 2025-10-09 10:40:21,588 django.server "OPTIONS /api/accounts/verify-otp/ HTTP/1.1" 200 0
[INFO] 2025-10-09 10:40:21,877 apps.accounts.api.views Successful login for 9168238418 (New user: False)
[INFO] 2025-10-09 10:40:21,880 django.server "POST /api/accounts/verify-otp/ HTTP/1.1" 200 570
[INFO] 2025-10-09 10:43:28,830 django.server "GET /admin/ HTTP/1.1" 200 9972
[WARNING] 2025-10-09 10:43:29,259 django.request Not Found: /favicon.ico
[WARNING] 2025-10-09 10:43:29,260 django.server "GET /favicon.ico HTTP/1.1" 404 2523
[INFO] 2025-10-10 22:39:39,907 django.utils.autoreload Watching for file changes with StatReloader
[INFO] 2025-10-10 22:45:37,446 django.utils.autoreload Watching for file changes with StatReloader
[INFO] 2025-10-10 22:48:47,103 django.utils.autoreload Watching for file changes with StatReloader
[INFO] 2025-10-10 22:49:58,021 django.server "OPTIONS /api/accounts/send-otp/ HTTP/1.1" 200 0
[INFO] 2025-10-10 22:49:58,121 apps.accounts.api.views OTP request received from IP: 10.157.72.214
[INFO] 2025-10-10 22:49:58,601 apps.accounts.api.views OTP generated for 9168238418: 878976
[INFO] 2025-10-10 22:49:58,632 django.server "POST /api/accounts/send-otp/ HTTP/1.1" 200 64
[INFO] 2025-10-10 22:50:20,130 django.server "OPTIONS /api/accounts/verify-otp/ HTTP/1.1" 200 0
[INFO] 2025-10-10 22:50:20,471 apps.accounts.api.views Successful login for 9168238418 (New user: False)
[INFO] 2025-10-10 22:50:20,472 django.server "POST /api/accounts/verify-otp/ HTTP/1.1" 200 570
[INFO] 2025-10-10 22:50:41,069 django.server "OPTIONS /api/bookings/ HTTP/1.1" 200 0
[INFO] 2025-10-10 22:50:41,194 apps.bookings.api.views Booking created: 4 for user 9168238418
[INFO] 2025-10-10 22:50:41,234 django.server "POST /api/bookings/ HTTP/1.1" 201 148
[INFO] 2025-10-11 14:50:05,903 django.utils.autoreload Watching for file changes with StatReloader
[INFO] 2025-10-11 14:50:22,003 django.server "OPTIONS /api/accounts/send-otp/ HTTP/1.1" 200 0
[INFO] 2025-10-11 14:50:22,071 apps.accounts.api.views OTP request received from IP: 10.157.72.214
[INFO] 2025-10-11 14:50:22,318 apps.accounts.api.views OTP generated for 9112666031: 131020
[INFO] 2025-10-11 14:50:22,322 django.server "POST /api/accounts/send-otp/ HTTP/1.1" 200 64
[INFO] 2025-10-11 14:50:31,528 django.server "OPTIONS /api/accounts/verify-otp/ HTTP/1.1" 200 0
[INFO] 2025-10-11 14:50:31,931 apps.accounts.api.views Successful login for 9112666031 (New user: False)
[INFO] 2025-10-11 14:50:31,937 django.server "POST /api/accounts/verify-otp/ HTTP/1.1" 200 570
[INFO] 2025-10-11 16:43:06,048 django.utils.autoreload Watching for file changes with StatReloader
[INFO] 2025-10-11 16:44:18,668 django.server "OPTIONS /api/accounts/send-otp/ HTTP/1.1" 200 0
[INFO] 2025-10-11 16:44:18,738 apps.accounts.api.views OTP request received from IP: 10.157.72.214
[INFO] 2025-10-11 16:44:18,910 apps.accounts.api.views OTP generated for 9112666031: 148612
[INFO] 2025-10-11 16:44:18,916 django.server "POST /api/accounts/send-otp/ HTTP/1.1" 200 64
[INFO] 2025-10-11 16:44:29,162 django.server "OPTIONS /api/accounts/verify-otp/ HTTP/1.1" 200 0
[INFO] 2025-10-11 16:44:29,567 apps.accounts.api.views Successful login for 9112666031 (New user: False)
[INFO] 2025-10-11 16:44:29,574 django.server "POST /api/accounts/verify-otp/ HTTP/1.1" 200 570
[INFO] 2025-10-11 16:44:36,598 django.server "OPTIONS /api/locations/addresses/ HTTP/1.1" 200 0
[INFO] 2025-10-11 16:44:36,895 django.server "GET /api/locations/addresses/ HTTP/1.1" 200 52
[INFO] 2025-10-11 16:46:45,473 django.server "OPTIONS /api/bookings/ HTTP/1.1" 200 0
[WARNING] 2025-10-11 16:46:46,406 apps.bookings.api.views Booking creation failed for 9112666031: {'date': [ErrorDetail(string='Date has wrong format. Use one of these formats instead: YYYY-MM-DD.', code='invalid')]}
[WARNING] 2025-10-11 16:46:46,457 django.request Bad Request: /api/bookings/
[WARNING] 2025-10-11 16:46:46,459 django.server "POST /api/bookings/ HTTP/1.1" 400 81
[WARNING] 2025-10-11 16:47:18,562 apps.bookings.api.views Booking creation failed for 9112666031: {'date': [ErrorDetail(string='Date has wrong format. Use one of these formats instead: YYYY-MM-DD.', code='invalid')]}
[WARNING] 2025-10-11 16:47:18,566 django.request Bad Request: /api/bookings/
[WARNING] 2025-10-11 16:47:18,567 django.server "POST /api/bookings/ HTTP/1.1" 400 81
[INFO] 2025-10-11 16:47:55,166 django.server "OPTIONS /api/auth/logout/ HTTP/1.1" 200 0
[WARNING] 2025-10-11 16:47:55,219 django.request Not Found: /api/auth/logout/
[WARNING] 2025-10-11 16:47:55,220 django.server "POST /api/auth/logout/ HTTP/1.1" 404 2700
[INFO] 2025-10-11 18:03:44,605 django.utils.autoreload Watching for file changes with StatReloader
[INFO] 2025-10-11 18:10:03,603 django.utils.autoreload Watching for file changes with StatReloader
[INFO] 2025-10-11 18:10:47,578 django.server "OPTIONS /api/accounts/send-otp/ HTTP/1.1" 200 0
[INFO] 2025-10-11 18:10:47,614 apps.accounts.api.views OTP request received from IP: 10.157.72.214
[INFO] 2025-10-11 18:10:47,826 apps.accounts.api.views New user created: 8999513014
[INFO] 2025-10-11 18:10:47,842 apps.accounts.api.views OTP generated for 8999513014: 153640
[INFO] 2025-10-11 18:10:47,869 django.server "POST /api/accounts/send-otp/ HTTP/1.1" 200 64
[INFO] 2025-10-11 18:10:59,431 django.server "OPTIONS /api/accounts/verify-otp/ HTTP/1.1" 200 0
[INFO] 2025-10-11 18:10:59,601 apps.accounts.api.views Successful login for 8999513014 (New user: False)
[INFO] 2025-10-11 18:10:59,603 django.server "POST /api/accounts/verify-otp/ HTTP/1.1" 200 570
[INFO] 2025-10-11 18:11:06,007 django.server "OPTIONS /api/locations/addresses/ HTTP/1.1" 200 0
[INFO] 2025-10-11 18:11:06,113 django.server "GET /api/locations/addresses/ HTTP/1.1" 200 52
[INFO] 2025-10-11 18:11:31,564 django.server "OPTIONS /api/bookings/ HTTP/1.1" 200 0
[INFO] 2025-10-11 18:11:31,650 apps.bookings.api.views Booking creation attempt by 8999513014: {'vehicle_type': 'car', 'date': ['2025-10-11', '00:00:00.000'], 'time_slot': '06:00 AM', 'notes': 'deep washing', 'latitude': 18.5246091, 'longitude': 73.8786239, 'service_address': 'Current Location'}
[WARNING] 2025-10-11 18:11:31,654 apps.bookings.api.views Booking creation validation failed for 8999513014: {'date': [ErrorDetail(string='Date has wrong format. Use one of these formats instead: YYYY-MM-DD.', code='invalid')], 'latitude': [ErrorDetail(string='Ensure that there are no more than 6 decimal places.', code='max_decimal_places')], 'longitude': [ErrorDetail(string='Ensure that there are no more than 6 decimal places.', code='max_decimal_places')]}
[WARNING] 2025-10-11 18:11:31,657 django.request Bad Request: /api/bookings/
[WARNING] 2025-10-11 18:11:31,658 django.server "POST /api/bookings/ HTTP/1.1" 400 218
[INFO] 2025-10-11 18:11:33,151 apps.bookings.api.views Booking creation attempt by 8999513014: {'vehicle_type': 'car', 'date': ['2025-10-11', '00:00:00.000'], 'time_slot': '06:00 AM', 'notes': 'deep washing', 'latitude': 18.5246091, 'longitude': 73.8786239, 'service_address': 'Current Location'}
[WARNING] 2025-10-11 18:11:33,153 apps.bookings.api.views Booking creation validation failed for 8999513014: {'date': [ErrorDetail(string='Date has wrong format. Use one of these formats instead: YYYY-MM-DD.', code='invalid')], 'latitude': [ErrorDetail(string='Ensure that there are no more than 6 decimal places.', code='max_decimal_places')], 'longitude': [ErrorDetail(string='Ensure that there are no more than 6 decimal places.', code='max_decimal_places')]}
[WARNING] 2025-10-11 18:11:33,154 django.request Bad Request: /api/bookings/
[WARNING] 2025-10-11 18:11:33,155 django.server "POST /api/bookings/ HTTP/1.1" 400 218
[INFO] 2025-10-11 18:23:12,884 django.utils.autoreload Watching for file changes with StatReloader
[INFO] 2025-10-11 18:24:13,149 django.server "OPTIONS /api/accounts/send-otp/ HTTP/1.1" 200 0
[INFO] 2025-10-11 18:24:13,175 apps.accounts.api.views OTP request received from IP: 10.157.72.214
[INFO] 2025-10-11 18:24:13,376 apps.accounts.api.views OTP generated for 8999513014: 694015
[INFO] 2025-10-11 18:24:13,383 django.server "POST /api/accounts/send-otp/ HTTP/1.1" 200 64
[INFO] 2025-10-11 18:24:23,515 django.server "OPTIONS /api/accounts/verify-otp/ HTTP/1.1" 200 0
[INFO] 2025-10-11 18:24:23,665 apps.accounts.api.views Successful login for 8999513014 (New user: False)
[INFO] 2025-10-11 18:24:23,667 django.server "POST /api/accounts/verify-otp/ HTTP/1.1" 200 570
[INFO] 2025-10-11 18:24:27,476 django.server "OPTIONS /api/locations/addresses/ HTTP/1.1" 200 0
[INFO] 2025-10-11 18:24:27,610 django.server "GET /api/locations/addresses/ HTTP/1.1" 200 52
[INFO] 2025-10-11 18:24:57,428 django.server "OPTIONS /api/bookings/ HTTP/1.1" 200 0
[INFO] 2025-10-11 18:24:57,520 apps.bookings.api.views Booking creation attempt by 8999513014: {'vehicle_type': 'car', 'date': '2025-10-11', 'time_slot': '09:00 PM', 'notes': 'deep cleaning', 'latitude': 18.524609, 'longitude': 73.878624, 'service_address': 'Current Location'}
[WARNING] 2025-10-11 18:24:57,531 apps.bookings.api.serializers No active service areas defined - allowing all locations
[WARNING] 2025-10-11 18:24:57,547 apps.bookings.models Booking None created outside service area: 18.524609, 73.878624
[INFO] 2025-10-11 18:24:57,560 apps.bookings.api.serializers Location-aware booking created: ID 1 at 18.524609, 73.878624 for user 8999513014
[INFO] 2025-10-11 18:24:57,562 apps.bookings.api.views Location-aware booking created successfully: ID 1 at Current Location (18.524609, 73.878624) for user 8999513014
[INFO] 2025-10-11 18:24:57,602 django.server "POST /api/bookings/ HTTP/1.1" 201 451
[INFO] 2025-10-11 23:03:33,517 django.utils.autoreload Watching for file changes with StatReloader
[INFO] 2025-10-12 10:30:00,068 django.utils.autoreload Watching for file changes with StatReloader
[INFO] 2025-10-12 13:43:16,306 django.utils.autoreload Watching for file changes with StatReloader
[INFO] 2025-10-12 14:42:44,330 django.utils.autoreload Watching for file changes with StatReloader
[INFO] 2025-10-12 15:49:28,930 django.utils.autoreload Watching for file changes with StatReloader
[INFO] 2025-10-12 15:57:27,544 apps.accounts.api.views OTP request received from IP: 10.157.72.214
[INFO] 2025-10-12 15:57:28,093 apps.accounts.api.views OTP generated for 8999513014: 632239
[INFO] 2025-10-12 15:57:28,114 django.server "POST /api/accounts/send-otp/ HTTP/1.1" 200 64
[INFO] 2025-10-12 15:57:47,181 apps.accounts.api.views Successful login for 8999513014 (New user: False)
[INFO] 2025-10-12 15:57:47,186 django.server "POST /api/accounts/verify-otp/ HTTP/1.1" 200 570
[INFO] 2025-10-12 15:58:03,492 django.server "GET /api/locations/addresses/ HTTP/1.1" 200 52
[WARNING] 2025-10-12 15:59:26,540 django.request Bad Request: /api/locations/addresses/
[WARNING] 2025-10-12 15:59:26,545 django.server "POST /api/locations/addresses/ HTTP/1.1" 400 140
[WARNING] 2025-10-12 16:00:49,691 django.request Bad Request: /api/locations/addresses/
[WARNING] 2025-10-12 16:00:49,701 django.server "POST /api/locations/addresses/ HTTP/1.1" 400 140
[WARNING] 2025-10-12 16:01:29,387 django.request Bad Request: /api/locations/addresses/
[WARNING] 2025-10-12 16:01:29,399 django.server "POST /api/locations/addresses/ HTTP/1.1" 400 140
[WARNING] 2025-10-12 16:01:34,713 django.request Bad Request: /api/locations/addresses/
[WARNING] 2025-10-12 16:01:34,725 django.server "POST /api/locations/addresses/ HTTP/1.1" 400 140
[WARNING] 2025-10-12 16:01:58,568 django.request Bad Request: /api/locations/addresses/
[WARNING] 2025-10-12 16:01:58,576 django.server "POST /api/locations/addresses/ HTTP/1.1" 400 140
[WARNING] 2025-10-12 16:02:17,187 django.request Bad Request: /api/locations/addresses/
[WARNING] 2025-10-12 16:02:17,195 django.server "POST /api/locations/addresses/ HTTP/1.1" 400 140
[INFO] 2025-10-12 16:15:58,726 django.utils.autoreload Watching for file changes with StatReloader
[INFO] 2025-10-12 16:19:08,201 apps.accounts.api.views Profile fetched for 8999513014
[INFO] 2025-10-12 16:19:08,254 django.server "GET /api/accounts/profile/ HTTP/1.1" 200 60
[INFO] 2025-10-12 16:23:43,578 django.utils.autoreload Watching for file changes with StatReloader
[INFO] 2025-10-12 16:25:50,418 django.server "OPTIONS /api/accounts/send-otp/ HTTP/1.1" 200 0
[INFO] 2025-10-12 16:25:51,087 apps.accounts.api.views OTP request received from IP: 10.157.72.214
[INFO] 2025-10-12 16:25:51,777 apps.accounts.api.views OTP generated for 8999513014: 769823
[INFO] 2025-10-12 16:25:51,843 django.server "POST /api/accounts/send-otp/ HTTP/1.1" 200 64
[INFO] 2025-10-12 16:26:03,791 django.server "OPTIONS /api/accounts/verify-otp/ HTTP/1.1" 200 0
[INFO] 2025-10-12 16:26:04,477 apps.accounts.api.views Successful login for 8999513014 (New user: False)
[INFO] 2025-10-12 16:26:04,483 django.server "POST /api/accounts/verify-otp/ HTTP/1.1" 200 570
[INFO] 2025-10-12 16:26:10,268 django.server "OPTIONS /api/locations/addresses/ HTTP/1.1" 200 0
[INFO] 2025-10-12 16:26:10,767 django.server "GET /api/locations/addresses/ HTTP/1.1" 200 52
[INFO] 2025-10-12 16:26:57,083 django.server "OPTIONS /api/bookings/ HTTP/1.1" 200 0
[INFO] 2025-10-12 16:26:57,516 apps.bookings.api.views Booking creation attempt by 8999513014: {'vehicle_type': 'car', 'date': '2025-10-12', 'time_slot': '01:00 PM', 'notes': 'deep cleaning', 'latitude': 18.524609, 'longitude': 73.878624, 'service_address': 'Current Location'}
[WARNING] 2025-10-12 16:26:57,615 apps.bookings.api.serializers No active service areas defined - allowing all locations
[WARNING] 2025-10-12 16:26:57,656 apps.bookings.models Booking None created outside service area: 18.524609, 73.878624
[INFO] 2025-10-12 16:26:57,693 apps.bookings.api.serializers Location-aware booking created: ID 2 at 18.524609, 73.878624 for user 8999513014
[INFO] 2025-10-12 16:26:57,695 apps.bookings.api.views Location-aware booking created successfully: ID 2 at Current Location (18.524609, 73.878624) for user 8999513014
[INFO] 2025-10-12 16:26:57,832 django.server "POST /api/bookings/ HTTP/1.1" 201 451
[INFO] 2025-10-13 16:17:53,114 django.utils.autoreload Watching for file changes with StatReloader
[INFO] 2025-10-13 16:23:02,870 django.utils.autoreload Watching for file changes with StatReloader
[INFO] 2025-10-13 16:24:14,428 django.server "OPTIONS /api/accounts/send-otp/ HTTP/1.1" 200 0
[INFO] 2025-10-13 16:24:14,508 apps.accounts.api.views OTP request received from IP: 10.219.56.214
[INFO] 2025-10-13 16:24:14,820 apps.accounts.api.views OTP generated for 8999513014: 517012
[INFO] 2025-10-13 16:24:14,825 django.server "POST /api/accounts/send-otp/ HTTP/1.1" 200 64
[INFO] 2025-10-13 16:24:24,214 django.server "OPTIONS /api/accounts/verify-otp/ HTTP/1.1" 200 0
[INFO] 2025-10-13 16:24:25,054 apps.accounts.api.views Successful login for 8999513014 (New user: False)
[INFO] 2025-10-13 16:24:25,059 django.server "POST /api/accounts/verify-otp/ HTTP/1.1" 200 570
[INFO] 2025-10-13 16:24:25,449 django.server "OPTIONS /api/bookings/ HTTP/1.1" 200 0
[INFO] 2025-10-13 16:24:25,625 apps.bookings.api.views Bookings listed for user 8999513014: 2 bookings
[INFO] 2025-10-13 16:24:25,710 django.server "GET /api/bookings/ HTTP/1.1" 200 846
[INFO] 2025-10-13 16:26:02,605 django.server "OPTIONS /api/locations/addresses/ HTTP/1.1" 200 0
[INFO] 2025-10-13 16:26:02,815 django.server "GET /api/locations/addresses/ HTTP/1.1" 200 52
[WARNING] 2025-10-13 16:27:09,431 django.request Bad Request: /api/locations/addresses/
[WARNING] 2025-10-13 16:27:09,435 django.server "POST /api/locations/addresses/ HTTP/1.1" 400 123
[WARNING] 2025-10-13 16:27:12,409 django.request Bad Request: /api/locations/addresses/
[WARNING] 2025-10-13 16:27:12,411 django.server "POST /api/locations/addresses/ HTTP/1.1" 400 123
[WARNING] 2025-10-13 16:27:13,226 django.request Bad Request: /api/locations/addresses/
[WARNING] 2025-10-13 16:27:13,228 django.server "POST /api/locations/addresses/ HTTP/1.1" 400 123
[WARNING] 2025-10-13 16:27:13,579 django.request Bad Request: /api/locations/addresses/
[WARNING] 2025-10-13 16:27:13,581 django.server "POST /api/locations/addresses/ HTTP/1.1" 400 123
[WARNING] 2025-10-13 16:27:13,935 django.request Bad Request: /api/locations/addresses/
[WARNING] 2025-10-13 16:27:13,937 django.server "POST /api/locations/addresses/ HTTP/1.1" 400 123
[WARNING] 2025-10-13 16:27:25,459 django.request Bad Request: /api/locations/addresses/
[WARNING] 2025-10-13 16:27:25,465 django.server "POST /api/locations/addresses/ HTTP/1.1" 400 123
[WARNING] 2025-10-13 16:27:28,572 django.request Bad Request: /api/locations/addresses/
[WARNING] 2025-10-13 16:27:28,576 django.server "POST /api/locations/addresses/ HTTP/1.1" 400 123
[WARNING] 2025-10-13 16:27:31,552 django.request Bad Request: /api/locations/addresses/
[WARNING] 2025-10-13 16:27:31,554 django.server "POST /api/locations/addresses/ HTTP/1.1" 400 123
[INFO] 2025-10-13 16:27:54,952 django.server "GET /api/locations/addresses/ HTTP/1.1" 200 52
[INFO] 2025-10-13 16:54:17,489 django.utils.autoreload Watching for file changes with StatReloader
[INFO] 2025-10-13 16:55:26,726 django.utils.autoreload Watching for file changes with StatReloader
[WARNING] 2025-10-13 17:10:52,341 django.request Unauthorized: /api/accounts/profile/
[WARNING] 2025-10-13 17:10:52,331 django.request Unauthorized: /api/bookings/
[WARNING] 2025-10-13 17:10:52,366 django.server "GET /api/accounts/profile/ HTTP/1.1" 401 172
[WARNING] 2025-10-13 17:10:52,378 django.server "GET /api/bookings/ HTTP/1.1" 401 172
[INFO] 2025-10-13 17:10:53,340 django.server "POST /api/accounts/token/refresh/ HTTP/1.1" 200 489
[INFO] 2025-10-13 17:10:53,357 django.server "POST /api/accounts/token/refresh/ HTTP/1.1" 200 489
[INFO] 2025-10-13 17:10:55,711 apps.bookings.api.views Bookings listed for user 8999513014: 2 bookings
[INFO] 2025-10-13 17:10:55,790 django.server "GET /api/bookings/ HTTP/1.1" 200 846
[INFO] 2025-10-13 17:10:56,458 apps.accounts.api.views Profile fetched for 8999513014
[INFO] 2025-10-13 17:10:56,463 django.server "GET /api/accounts/profile/ HTTP/1.1" 200 60
[INFO] 2025-10-13 17:11:18,313 apps.accounts.api.views Profile fetched for 8999513014
[INFO] 2025-10-13 17:11:18,316 django.server "GET /api/accounts/profile/ HTTP/1.1" 200 60
[INFO] 2025-10-13 17:11:47,219 django.server "GET /api/locations/addresses/ HTTP/1.1" 200 52
[INFO] 2025-10-13 17:11:51,968 apps.bookings.api.views Bookings listed for user 8999513014: 2 bookings
[INFO] 2025-10-13 17:11:52,015 django.server "GET /api/bookings/ HTTP/1.1" 200 846
[INFO] 2025-10-13 17:12:47,991 apps.accounts.api.views Profile fetched for 8999513014
[INFO] 2025-10-13 17:12:48,002 django.server "GET /api/accounts/profile/ HTTP/1.1" 200 60
[INFO] 2025-10-13 17:14:26,931 apps.accounts.api.views Profile updated for 8999513014
[INFO] 2025-10-13 17:14:26,934 django.server "PUT /api/accounts/profile/ HTTP/1.1" 200 90
[INFO] 2025-10-13 17:14:27,224 apps.accounts.api.views Profile fetched for 8999513014
[INFO] 2025-10-13 17:14:27,226 django.server "GET /api/accounts/profile/ HTTP/1.1" 200 90
[INFO] 2025-10-13 17:19:49,257 django.server "GET /api/locations/addresses/ HTTP/1.1" 200 52
[INFO] 2025-10-13 17:24:12,556 apps.accounts.api.views Profile fetched for 8999513014
[INFO] 2025-10-13 17:24:12,639 apps.bookings.api.views Bookings listed for user 8999513014: 2 bookings
[INFO] 2025-10-13 17:24:12,681 django.server "GET /api/accounts/profile/ HTTP/1.1" 200 90
[INFO] 2025-10-13 17:24:12,749 django.server "GET /api/bookings/ HTTP/1.1" 200 868
[INFO] 2025-10-13 17:39:40,430 django.utils.autoreload Watching for file changes with StatReloader
[INFO] 2025-10-13 17:43:24,221 apps.accounts.api.views Profile fetched for 8999513014
[INFO] 2025-10-13 17:43:24,244 apps.bookings.api.views Bookings listed for user 8999513014: 2 bookings
[INFO] 2025-10-13 17:43:24,280 django.server "GET /api/accounts/profile/ HTTP/1.1" 200 90
[INFO] 2025-10-13 17:43:24,322 django.server "GET /api/bookings/ HTTP/1.1" 200 868
[INFO] 2025-10-13 17:47:28,629 django.server "GET /api/locations/addresses/ HTTP/1.1" 200 52
[INFO] 2025-10-13 17:49:18,627 apps.accounts.api.views Profile fetched for 8999513014
[INFO] 2025-10-13 17:49:18,656 apps.bookings.api.views Bookings listed for user 8999513014: 2 bookings
[INFO] 2025-10-13 17:49:18,746 django.server "GET /api/accounts/profile/ HTTP/1.1" 200 90
[INFO] 2025-10-13 17:49:18,780 django.server "GET /api/bookings/ HTTP/1.1" 200 868
[INFO] 2025-10-13 17:49:32,957 django.server "GET /api/locations/addresses/ HTTP/1.1" 200 52
[INFO] 2025-10-13 17:56:24,087 apps.accounts.api.views Profile fetched for 8999513014
[INFO] 2025-10-13 17:56:24,096 apps.bookings.api.views Bookings listed for user 8999513014: 2 bookings
[INFO] 2025-10-13 17:56:24,186 django.server "GET /api/accounts/profile/ HTTP/1.1" 200 90
[INFO] 2025-10-13 17:56:24,201 django.server "GET /api/bookings/ HTTP/1.1" 200 868
[INFO] 2025-10-13 18:10:02,735 django.utils.autoreload Watching for file changes with StatReloader
[INFO] 2025-10-13 18:12:59,886 django.server "OPTIONS /api/accounts/send-otp/ HTTP/1.1" 200 0
[INFO] 2025-10-13 18:13:01,129 apps.accounts.api.views OTP request received from IP: 10.219.56.214
[INFO] 2025-10-13 18:13:02,360 apps.accounts.api.views New user created: 9112666031
[INFO] 2025-10-13 18:13:02,379 apps.accounts.api.views OTP generated for 9112666031: 652078
[INFO] 2025-10-13 18:13:02,487 django.server "POST /api/accounts/send-otp/ HTTP/1.1" 200 64
[INFO] 2025-10-13 18:13:16,671 django.server "OPTIONS /api/accounts/verify-otp/ HTTP/1.1" 200 0
[INFO] 2025-10-13 18:13:18,577 apps.accounts.api.views Successful login for 9112666031 (New user: False)
[INFO] 2025-10-13 18:13:18,734 django.server "POST /api/accounts/verify-otp/ HTTP/1.1" 200 570
[INFO] 2025-10-13 18:13:19,934 django.server "OPTIONS /api/bookings/ HTTP/1.1" 200 0
[INFO] 2025-10-13 18:13:21,239 apps.bookings.api.views Bookings listed for user 9112666031: 0 bookings
[INFO] 2025-10-13 18:13:21,259 django.server "GET /api/bookings/ HTTP/1.1" 200 25
[INFO] 2025-10-13 18:14:09,702 django.server "OPTIONS /api/locations/addresses/ HTTP/1.1" 200 0
[INFO] 2025-10-13 18:14:11,304 django.server "GET /api/locations/addresses/ HTTP/1.1" 200 52
[WARNING] 2025-10-13 18:14:35,510 django.request Bad Request: /api/locations/addresses/
[WARNING] 2025-10-13 18:14:35,519 django.server "POST /api/locations/addresses/ HTTP/1.1" 400 123
[WARNING] 2025-10-13 18:14:37,026 django.request Bad Request: /api/locations/addresses/
[WARNING] 2025-10-13 18:14:37,031 django.server "POST /api/locations/addresses/ HTTP/1.1" 400 123
[WARNING] 2025-10-13 18:14:38,729 django.request Bad Request: /api/locations/addresses/
[WARNING] 2025-10-13 18:14:38,828 django.server "POST /api/locations/addresses/ HTTP/1.1" 400 123
[INFO] 2025-10-13 20:49:54,707 django.utils.autoreload Watching for file changes with StatReloader
[INFO] 2025-10-13 20:51:06,625 django.server "OPTIONS /api/accounts/send-otp/ HTTP/1.1" 200 0
[INFO] 2025-10-13 20:51:06,645 apps.accounts.api.views OTP request received from IP: 10.219.56.214
[INFO] 2025-10-13 20:51:06,853 apps.accounts.api.views OTP generated for 9112666031: 032005
[INFO] 2025-10-13 20:51:06,856 django.server "POST /api/accounts/send-otp/ HTTP/1.1" 200 64
[INFO] 2025-10-13 20:51:17,812 django.server "OPTIONS /api/accounts/verify-otp/ HTTP/1.1" 200 0
[INFO] 2025-10-13 20:51:17,981 apps.accounts.api.views Successful login for 9112666031 (New user: False)
[INFO] 2025-10-13 20:51:17,983 django.server "POST /api/accounts/verify-otp/ HTTP/1.1" 200 570
[INFO] 2025-10-13 20:51:18,252 django.server "OPTIONS /api/bookings/ HTTP/1.1" 200 0
[INFO] 2025-10-13 20:51:18,341 apps.bookings.api.views Bookings listed for user 9112666031: 0 bookings
[INFO] 2025-10-13 20:51:18,346 django.server "GET /api/bookings/ HTTP/1.1" 200 25
[WARNING] 2025-10-13 20:57:09,832 django.request Unauthorized: /api/accounts/profile/
[WARNING] 2025-10-13 20:57:09,840 django.request Unauthorized: /api/bookings/
[WARNING] 2025-10-13 20:57:09,875 django.server "GET /api/bookings/ HTTP/1.1" 401 172
[WARNING] 2025-10-13 20:57:09,879 django.server "GET /api/accounts/profile/ HTTP/1.1" 401 172
[ERROR] 2025-10-13 20:57:15,440 django.request Internal Server Error: /api/accounts/token/refresh/
Traceback (most recent call last):
  File "C:\Users\2001k\AppData\Local\Programs\Python\Python313\Lib\site-packages\django\core\handlers\exception.py", line 55, in inner
    response = get_response(request)
  File "C:\Users\2001k\AppData\Local\Programs\Python\Python313\Lib\site-packages\django\core\handlers\base.py", line 197, in _get_response
    response = wrapped_callback(request, *callback_args, **callback_kwargs)
  File "C:\Users\2001k\AppData\Local\Programs\Python\Python313\Lib\site-packages\django\views\decorators\csrf.py", line 65, in _view_wrapper
    return view_func(request, *args, **kwargs)
  File "C:\Users\2001k\AppData\Local\Programs\Python\Python313\Lib\site-packages\django\views\generic\base.py", line 105, in view
    return self.dispatch(request, *args, **kwargs)
           ~~~~~~~~~~~~~^^^^^^^^^^^^^^^^^^^^^^^^^^
  File "C:\Users\2001k\AppData\Local\Programs\Python\Python313\Lib\site-packages\rest_framework\views.py", line 515, in dispatch
    response = self.handle_exception(exc)
  File "C:\Users\2001k\AppData\Local\Programs\Python\Python313\Lib\site-packages\rest_framework\views.py", line 475, in handle_exception
    self.raise_uncaught_exception(exc)
    ~~~~~~~~~~~~~~~~~~~~~~~~~~~~~^^^^^
  File "C:\Users\2001k\AppData\Local\Programs\Python\Python313\Lib\site-packages\rest_framework\views.py", line 486, in raise_uncaught_exception
    raise exc
  File "C:\Users\2001k\AppData\Local\Programs\Python\Python313\Lib\site-packages\rest_framework\views.py", line 512, in dispatch
    response = handler(request, *args, **kwargs)
  File "C:\Users\2001k\AppData\Local\Programs\Python\Python313\Lib\site-packages\rest_framework_simplejwt\views.py", line 46, in post
    serializer.is_valid(raise_exception=True)
    ~~~~~~~~~~~~~~~~~~~^^^^^^^^^^^^^^^^^^^^^^
  File "C:\Users\2001k\AppData\Local\Programs\Python\Python313\Lib\site-packages\rest_framework\serializers.py", line 225, in is_valid
    self._validated_data = self.run_validation(self.initial_data)
                           ~~~~~~~~~~~~~~~~~~~^^^^^^^^^^^^^^^^^^^
  File "C:\Users\2001k\AppData\Local\Programs\Python\Python313\Lib\site-packages\rest_framework\serializers.py", line 447, in run_validation
    value = self.validate(value)
  File "C:\Users\2001k\AppData\Local\Programs\Python\Python313\Lib\site-packages\rest_framework_simplejwt\serializers.py", line 116, in validate
    user := get_user_model().objects.get(
            ~~~~~~~~~~~~~~~~~~~~~~~~~~~~^
        **{api_settings.USER_ID_FIELD: user_id}
        ^^^^^^^^^^^^^^^^^^^^^^^^^^^^^^^^^^^^^^^
    )
    ^
  File "C:\Users\2001k\AppData\Local\Programs\Python\Python313\Lib\site-packages\django\db\models\manager.py", line 87, in manager_method
    return getattr(self.get_queryset(), name)(*args, **kwargs)
           ~~~~~~~~~~~~~~~~~~~~~~~~~~~~~~~~~~^^^^^^^^^^^^^^^^^
  File "C:\Users\2001k\AppData\Local\Programs\Python\Python313\Lib\site-packages\django\db\models\query.py", line 633, in get
    raise self.model.DoesNotExist(
        "%s matching query does not exist." % self.model._meta.object_name
    )
apps.accounts.models.User.DoesNotExist: User matching query does not exist.
[ERROR] 2025-10-13 20:57:15,448 django.request Internal Server Error: /api/accounts/token/refresh/
Traceback (most recent call last):
  File "C:\Users\2001k\AppData\Local\Programs\Python\Python313\Lib\site-packages\django\core\handlers\exception.py", line 55, in inner
    response = get_response(request)
  File "C:\Users\2001k\AppData\Local\Programs\Python\Python313\Lib\site-packages\django\core\handlers\base.py", line 197, in _get_response
    response = wrapped_callback(request, *callback_args, **callback_kwargs)
  File "C:\Users\2001k\AppData\Local\Programs\Python\Python313\Lib\site-packages\django\views\decorators\csrf.py", line 65, in _view_wrapper
    return view_func(request, *args, **kwargs)
  File "C:\Users\2001k\AppData\Local\Programs\Python\Python313\Lib\site-packages\django\views\generic\base.py", line 105, in view
    return self.dispatch(request, *args, **kwargs)
           ~~~~~~~~~~~~~^^^^^^^^^^^^^^^^^^^^^^^^^^
  File "C:\Users\2001k\AppData\Local\Programs\Python\Python313\Lib\site-packages\rest_framework\views.py", line 515, in dispatch
    response = self.handle_exception(exc)
  File "C:\Users\2001k\AppData\Local\Programs\Python\Python313\Lib\site-packages\rest_framework\views.py", line 475, in handle_exception
    self.raise_uncaught_exception(exc)
    ~~~~~~~~~~~~~~~~~~~~~~~~~~~~~^^^^^
  File "C:\Users\2001k\AppData\Local\Programs\Python\Python313\Lib\site-packages\rest_framework\views.py", line 486, in raise_uncaught_exception
    raise exc
  File "C:\Users\2001k\AppData\Local\Programs\Python\Python313\Lib\site-packages\rest_framework\views.py", line 512, in dispatch
    response = handler(request, *args, **kwargs)
  File "C:\Users\2001k\AppData\Local\Programs\Python\Python313\Lib\site-packages\rest_framework_simplejwt\views.py", line 46, in post
    serializer.is_valid(raise_exception=True)
    ~~~~~~~~~~~~~~~~~~~^^^^^^^^^^^^^^^^^^^^^^
  File "C:\Users\2001k\AppData\Local\Programs\Python\Python313\Lib\site-packages\rest_framework\serializers.py", line 225, in is_valid
    self._validated_data = self.run_validation(self.initial_data)
                           ~~~~~~~~~~~~~~~~~~~^^^^^^^^^^^^^^^^^^^
  File "C:\Users\2001k\AppData\Local\Programs\Python\Python313\Lib\site-packages\rest_framework\serializers.py", line 447, in run_validation
    value = self.validate(value)
  File "C:\Users\2001k\AppData\Local\Programs\Python\Python313\Lib\site-packages\rest_framework_simplejwt\serializers.py", line 116, in validate
    user := get_user_model().objects.get(
            ~~~~~~~~~~~~~~~~~~~~~~~~~~~~^
        **{api_settings.USER_ID_FIELD: user_id}
        ^^^^^^^^^^^^^^^^^^^^^^^^^^^^^^^^^^^^^^^
    )
    ^
  File "C:\Users\2001k\AppData\Local\Programs\Python\Python313\Lib\site-packages\django\db\models\manager.py", line 87, in manager_method
    return getattr(self.get_queryset(), name)(*args, **kwargs)
           ~~~~~~~~~~~~~~~~~~~~~~~~~~~~~~~~~~^^^^^^^^^^^^^^^^^
  File "C:\Users\2001k\AppData\Local\Programs\Python\Python313\Lib\site-packages\django\db\models\query.py", line 633, in get
    raise self.model.DoesNotExist(
        "%s matching query does not exist." % self.model._meta.object_name
    )
apps.accounts.models.User.DoesNotExist: User matching query does not exist.
[INFO] 2025-10-13 20:57:15,535 django.server - Broken pipe from ('10.219.56.214', 60361)
[INFO] 2025-10-13 20:57:15,539 django.server - Broken pipe from ('10.219.56.214', 60360)
[INFO] 2025-10-13 20:59:25,834 django.utils.autoreload Watching for file changes with StatReloader
[WARNING] 2025-10-13 21:03:35,320 django.request Unauthorized: /api/bookings/
[WARNING] 2025-10-13 21:03:35,298 django.request Unauthorized: /api/accounts/profile/
[WARNING] 2025-10-13 21:03:35,359 django.server "GET /api/bookings/ HTTP/1.1" 401 172
[WARNING] 2025-10-13 21:03:35,361 django.server "GET /api/accounts/profile/ HTTP/1.1" 401 172
[ERROR] 2025-10-13 21:03:37,011 django.request Internal Server Error: /api/accounts/token/refresh/
Traceback (most recent call last):
  File "C:\Users\2001k\AppData\Local\Programs\Python\Python313\Lib\site-packages\django\core\handlers\exception.py", line 55, in inner
    response = get_response(request)
  File "C:\Users\2001k\AppData\Local\Programs\Python\Python313\Lib\site-packages\django\core\handlers\base.py", line 197, in _get_response
    response = wrapped_callback(request, *callback_args, **callback_kwargs)
  File "C:\Users\2001k\AppData\Local\Programs\Python\Python313\Lib\site-packages\django\views\decorators\csrf.py", line 65, in _view_wrapper
    return view_func(request, *args, **kwargs)
  File "C:\Users\2001k\AppData\Local\Programs\Python\Python313\Lib\site-packages\django\views\generic\base.py", line 105, in view
    return self.dispatch(request, *args, **kwargs)
           ~~~~~~~~~~~~~^^^^^^^^^^^^^^^^^^^^^^^^^^
  File "C:\Users\2001k\AppData\Local\Programs\Python\Python313\Lib\site-packages\rest_framework\views.py", line 515, in dispatch
    response = self.handle_exception(exc)
  File "C:\Users\2001k\AppData\Local\Programs\Python\Python313\Lib\site-packages\rest_framework\views.py", line 475, in handle_exception
    self.raise_uncaught_exception(exc)
    ~~~~~~~~~~~~~~~~~~~~~~~~~~~~~^^^^^
  File "C:\Users\2001k\AppData\Local\Programs\Python\Python313\Lib\site-packages\rest_framework\views.py", line 486, in raise_uncaught_exception
    raise exc
  File "C:\Users\2001k\AppData\Local\Programs\Python\Python313\Lib\site-packages\rest_framework\views.py", line 512, in dispatch
    response = handler(request, *args, **kwargs)
  File "C:\Users\2001k\AppData\Local\Programs\Python\Python313\Lib\site-packages\rest_framework_simplejwt\views.py", line 46, in post
    serializer.is_valid(raise_exception=True)
    ~~~~~~~~~~~~~~~~~~~^^^^^^^^^^^^^^^^^^^^^^
  File "C:\Users\2001k\AppData\Local\Programs\Python\Python313\Lib\site-packages\rest_framework\serializers.py", line 225, in is_valid
    self._validated_data = self.run_validation(self.initial_data)
                           ~~~~~~~~~~~~~~~~~~~^^^^^^^^^^^^^^^^^^^
  File "C:\Users\2001k\AppData\Local\Programs\Python\Python313\Lib\site-packages\rest_framework\serializers.py", line 447, in run_validation
    value = self.validate(value)
  File "C:\Users\2001k\AppData\Local\Programs\Python\Python313\Lib\site-packages\rest_framework_simplejwt\serializers.py", line 116, in validate
    user := get_user_model().objects.get(
            ~~~~~~~~~~~~~~~~~~~~~~~~~~~~^
        **{api_settings.USER_ID_FIELD: user_id}
        ^^^^^^^^^^^^^^^^^^^^^^^^^^^^^^^^^^^^^^^
    )
    ^
  File "C:\Users\2001k\AppData\Local\Programs\Python\Python313\Lib\site-packages\django\db\models\manager.py", line 87, in manager_method
    return getattr(self.get_queryset(), name)(*args, **kwargs)
           ~~~~~~~~~~~~~~~~~~~~~~~~~~~~~~~~~~^^^^^^^^^^^^^^^^^
  File "C:\Users\2001k\AppData\Local\Programs\Python\Python313\Lib\site-packages\django\db\models\query.py", line 633, in get
    raise self.model.DoesNotExist(
        "%s matching query does not exist." % self.model._meta.object_name
    )
apps.accounts.models.User.DoesNotExist: User matching query does not exist.
[ERROR] 2025-10-13 21:03:37,071 django.request Internal Server Error: /api/accounts/token/refresh/
Traceback (most recent call last):
  File "C:\Users\2001k\AppData\Local\Programs\Python\Python313\Lib\site-packages\django\core\handlers\exception.py", line 55, in inner
    response = get_response(request)
  File "C:\Users\2001k\AppData\Local\Programs\Python\Python313\Lib\site-packages\django\core\handlers\base.py", line 197, in _get_response
    response = wrapped_callback(request, *callback_args, **callback_kwargs)
  File "C:\Users\2001k\AppData\Local\Programs\Python\Python313\Lib\site-packages\django\views\decorators\csrf.py", line 65, in _view_wrapper
    return view_func(request, *args, **kwargs)
  File "C:\Users\2001k\AppData\Local\Programs\Python\Python313\Lib\site-packages\django\views\generic\base.py", line 105, in view
    return self.dispatch(request, *args, **kwargs)
           ~~~~~~~~~~~~~^^^^^^^^^^^^^^^^^^^^^^^^^^
  File "C:\Users\2001k\AppData\Local\Programs\Python\Python313\Lib\site-packages\rest_framework\views.py", line 515, in dispatch
    response = self.handle_exception(exc)
  File "C:\Users\2001k\AppData\Local\Programs\Python\Python313\Lib\site-packages\rest_framework\views.py", line 475, in handle_exception
    self.raise_uncaught_exception(exc)
    ~~~~~~~~~~~~~~~~~~~~~~~~~~~~~^^^^^
  File "C:\Users\2001k\AppData\Local\Programs\Python\Python313\Lib\site-packages\rest_framework\views.py", line 486, in raise_uncaught_exception
    raise exc
  File "C:\Users\2001k\AppData\Local\Programs\Python\Python313\Lib\site-packages\rest_framework\views.py", line 512, in dispatch
    response = handler(request, *args, **kwargs)
  File "C:\Users\2001k\AppData\Local\Programs\Python\Python313\Lib\site-packages\rest_framework_simplejwt\views.py", line 46, in post
    serializer.is_valid(raise_exception=True)
    ~~~~~~~~~~~~~~~~~~~^^^^^^^^^^^^^^^^^^^^^^
  File "C:\Users\2001k\AppData\Local\Programs\Python\Python313\Lib\site-packages\rest_framework\serializers.py", line 225, in is_valid
    self._validated_data = self.run_validation(self.initial_data)
                           ~~~~~~~~~~~~~~~~~~~^^^^^^^^^^^^^^^^^^^
  File "C:\Users\2001k\AppData\Local\Programs\Python\Python313\Lib\site-packages\rest_framework\serializers.py", line 447, in run_validation
    value = self.validate(value)
  File "C:\Users\2001k\AppData\Local\Programs\Python\Python313\Lib\site-packages\rest_framework_simplejwt\serializers.py", line 116, in validate
    user := get_user_model().objects.get(
            ~~~~~~~~~~~~~~~~~~~~~~~~~~~~^
        **{api_settings.USER_ID_FIELD: user_id}
        ^^^^^^^^^^^^^^^^^^^^^^^^^^^^^^^^^^^^^^^
    )
    ^
  File "C:\Users\2001k\AppData\Local\Programs\Python\Python313\Lib\site-packages\django\db\models\manager.py", line 87, in manager_method
    return getattr(self.get_queryset(), name)(*args, **kwargs)
           ~~~~~~~~~~~~~~~~~~~~~~~~~~~~~~~~~~^^^^^^^^^^^^^^^^^
  File "C:\Users\2001k\AppData\Local\Programs\Python\Python313\Lib\site-packages\django\db\models\query.py", line 633, in get
    raise self.model.DoesNotExist(
        "%s matching query does not exist." % self.model._meta.object_name
    )
apps.accounts.models.User.DoesNotExist: User matching query does not exist.
[ERROR] 2025-10-13 21:03:37,081 django.server "POST /api/accounts/token/refresh/ HTTP/1.1" 500 122680
[ERROR] 2025-10-13 21:03:37,092 django.server "POST /api/accounts/token/refresh/ HTTP/1.1" 500 122680
[INFO] 2025-10-13 21:06:06,323 django.utils.autoreload Watching for file changes with StatReloader
[INFO] 2025-10-13 21:08:01,709 django.server "OPTIONS /api/accounts/send-otp/ HTTP/1.1" 200 0
[INFO] 2025-10-13 21:08:01,736 apps.accounts.api.views OTP request received from IP: 10.219.56.214
[INFO] 2025-10-13 21:08:01,983 apps.accounts.api.views New user created: 8999513014
[INFO] 2025-10-13 21:08:01,999 apps.accounts.api.views OTP generated for 8999513014: 007468
[INFO] 2025-10-13 21:08:02,041 django.server "POST /api/accounts/send-otp/ HTTP/1.1" 200 64
[INFO] 2025-10-13 21:08:13,472 django.server "OPTIONS /api/accounts/verify-otp/ HTTP/1.1" 200 0
[INFO] 2025-10-13 21:08:13,651 apps.accounts.api.views Successful login for 8999513014 (New user: False)
[INFO] 2025-10-13 21:08:13,653 django.server "POST /api/accounts/verify-otp/ HTTP/1.1" 200 570
[INFO] 2025-10-13 21:08:13,932 django.server "OPTIONS /api/bookings/ HTTP/1.1" 200 0
[INFO] 2025-10-13 21:08:14,034 apps.bookings.api.views Bookings listed for user 8999513014: 0 bookings
[INFO] 2025-10-13 21:08:14,040 django.server "GET /api/bookings/ HTTP/1.1" 200 25
[INFO] 2025-10-13 21:08:29,508 django.server "OPTIONS /api/locations/addresses/ HTTP/1.1" 200 0
[INFO] 2025-10-13 21:08:29,714 django.server "GET /api/locations/addresses/ HTTP/1.1" 200 52
[WARNING] 2025-10-13 21:08:48,061 django.request Bad Request: /api/locations/addresses/
[WARNING] 2025-10-13 21:08:48,064 django.server "POST /api/locations/addresses/ HTTP/1.1" 400 123
[INFO] 2025-10-13 21:21:43,935 django.utils.autoreload Watching for file changes with StatReloader
[INFO] 2025-10-13 21:34:31,787 django.server "OPTIONS /api/accounts/send-otp/ HTTP/1.1" 200 0
[INFO] 2025-10-13 21:34:34,205 apps.accounts.api.views OTP request received from IP: 10.219.56.214
[INFO] 2025-10-13 21:34:35,352 apps.accounts.api.views OTP generated for 9112666031: 420508
[INFO] 2025-10-13 21:34:35,386 django.server "POST /api/accounts/send-otp/ HTTP/1.1" 200 64
[INFO] 2025-10-13 21:34:49,745 django.server "OPTIONS /api/accounts/verify-otp/ HTTP/1.1" 200 0
[INFO] 2025-10-13 21:34:51,229 apps.accounts.api.views Successful login for 9112666031 (New user: False)
[INFO] 2025-10-13 21:34:51,238 django.server "POST /api/accounts/verify-otp/ HTTP/1.1" 200 570
[INFO] 2025-10-13 21:34:51,741 django.server "OPTIONS /api/bookings/ HTTP/1.1" 200 0
[INFO] 2025-10-13 21:34:51,985 apps.bookings.api.views Bookings listed for user 9112666031: 0 bookings
[INFO] 2025-10-13 21:34:52,013 django.server "GET /api/bookings/ HTTP/1.1" 200 25
[INFO] 2025-10-13 21:35:04,486 django.server "OPTIONS /api/locations/addresses/ HTTP/1.1" 200 0
[INFO] 2025-10-13 21:35:04,721 django.server "GET /api/locations/addresses/ HTTP/1.1" 200 52
[INFO] 2025-10-13 21:35:12,469 django.server "GET /api/locations/addresses/ HTTP/1.1" 200 52
[WARNING] 2025-10-13 21:35:45,201 django.request Bad Request: /api/locations/addresses/
[WARNING] 2025-10-13 21:35:45,206 django.server "POST /api/locations/addresses/ HTTP/1.1" 400 123
[WARNING] 2025-10-13 22:53:03,031 django.request Not Found: /
[WARNING] 2025-10-13 22:53:03,038 django.server "GET / HTTP/1.1" 404 2633
[WARNING] 2025-10-13 22:53:22,464 django.request Not Found: /
[INFO] 2025-10-13 22:53:22,468 django.server - Broken pipe from ('10.219.56.214', 52027)
[WARNING] 2025-10-13 22:53:22,478 django.request Not Found: /loginMsg.js
[WARNING] 2025-10-13 22:53:22,480 django.server "GET /loginMsg.js HTTP/1.1" 404 2679
[WARNING] 2025-10-13 22:53:22,492 django.request Not Found: /cgi/get.cgi
[WARNING] 2025-10-13 22:53:22,495 django.server "GET /cgi/get.cgi?cmd=home_login HTTP/1.1" 404 2694
[INFO] 2025-10-13 23:16:09,422 django.utils.autoreload Watching for file changes with StatReloader
[INFO] 2025-10-13 23:22:11,096 django.server "OPTIONS /api/accounts/send-otp/ HTTP/1.1" 200 0
[INFO] 2025-10-13 23:22:11,183 apps.accounts.api.views OTP request received from IP: 10.219.56.214
[INFO] 2025-10-13 23:22:11,429 apps.accounts.api.views OTP generated for 9112666031: 581621
[INFO] 2025-10-13 23:22:11,431 django.server "POST /api/accounts/send-otp/ HTTP/1.1" 200 64
[INFO] 2025-10-13 23:22:24,375 django.server "OPTIONS /api/accounts/verify-otp/ HTTP/1.1" 200 0
[INFO] 2025-10-13 23:22:24,592 apps.accounts.api.views Successful login for 9112666031 (New user: False)
[INFO] 2025-10-13 23:22:24,593 django.server "POST /api/accounts/verify-otp/ HTTP/1.1" 200 570
[INFO] 2025-10-13 23:22:24,900 django.server "OPTIONS /api/bookings/ HTTP/1.1" 200 0
[INFO] 2025-10-13 23:22:25,018 apps.bookings.api.views Bookings listed for user 9112666031: 0 bookings
[INFO] 2025-10-13 23:22:25,030 django.server "GET /api/bookings/ HTTP/1.1" 200 25
[INFO] 2025-10-13 23:22:36,708 django.server "OPTIONS /api/locations/addresses/ HTTP/1.1" 200 0
[INFO] 2025-10-13 23:22:36,877 django.server "GET /api/locations/addresses/ HTTP/1.1" 200 52
[INFO] 2025-10-13 23:26:46,207 django.server "GET /api/locations/addresses/ HTTP/1.1" 200 52
[INFO] 2025-10-13 23:26:54,189 django.server "GET /api/locations/addresses/ HTTP/1.1" 200 52
[INFO] 2025-10-14 08:56:06,951 django.utils.autoreload Watching for file changes with StatReloader
[INFO] 2025-10-14 09:05:30,740 django.utils.autoreload Watching for file changes with StatReloader
[INFO] 2025-10-14 12:04:30,264 django.utils.autoreload Watching for file changes with StatReloader
[INFO] 2025-10-14 12:07:13,907 django.server "OPTIONS /api/accounts/send-otp/ HTTP/1.1" 200 0
[INFO] 2025-10-14 12:07:14,129 apps.accounts.api.views OTP request received from IP: 10.219.56.214
[INFO] 2025-10-14 12:07:14,341 apps.accounts.api.views New user created: 8999513014
[INFO] 2025-10-14 12:07:14,347 apps.accounts.api.views OTP generated for 8999513014: 801550
[INFO] 2025-10-14 12:07:14,350 django.server "POST /api/accounts/send-otp/ HTTP/1.1" 200 64
[INFO] 2025-10-14 12:07:23,830 django.server "OPTIONS /api/accounts/verify-otp/ HTTP/1.1" 200 0
[INFO] 2025-10-14 12:07:24,152 apps.accounts.api.views Successful login for 8999513014 (New user: False)
[INFO] 2025-10-14 12:07:24,154 django.server "POST /api/accounts/verify-otp/ HTTP/1.1" 200 570
[INFO] 2025-10-14 12:07:24,570 django.server "OPTIONS /api/bookings/ HTTP/1.1" 200 0
[INFO] 2025-10-14 12:07:24,698 apps.bookings.api.views Bookings listed for user 8999513014: 0 bookings
[INFO] 2025-10-14 12:07:24,707 django.server "GET /api/bookings/ HTTP/1.1" 200 2
[INFO] 2025-10-14 12:07:33,989 django.server "OPTIONS /api/locations/addresses/ HTTP/1.1" 200 0
[INFO] 2025-10-14 12:07:34,103 django.server "GET /api/locations/addresses/ HTTP/1.1" 200 52
[WARNING] 2025-10-14 12:07:45,967 django.request Bad Request: /api/locations/addresses/
[WARNING] 2025-10-14 12:07:45,968 django.server "POST /api/locations/addresses/ HTTP/1.1" 400 80
[INFO] 2025-10-14 12:12:05,288 django.utils.autoreload C:\Users\2001k\Downloads\Auto_Care_App-master\Auto_Care_App-master\auto_care_backend\apps\locations\models.py changed, reloading.
[INFO] 2025-10-14 12:12:07,212 django.utils.autoreload Watching for file changes with StatReloader
[INFO] 2025-10-14 12:12:41,005 django.utils.autoreload C:\Users\2001k\Downloads\Auto_Care_App-master\Auto_Care_App-master\auto_care_backend\apps\locations\api\serializers.py changed, reloading.
[INFO] 2025-10-14 12:12:42,016 django.utils.autoreload Watching for file changes with StatReloader
[INFO] 2025-10-14 12:13:21,024 django.utils.autoreload C:\Users\2001k\Downloads\Auto_Care_App-master\Auto_Care_App-master\auto_care_backend\apps\locations\api\serializers.py changed, reloading.
[INFO] 2025-10-14 12:13:22,829 django.utils.autoreload Watching for file changes with StatReloader
[INFO] 2025-10-14 12:13:28,742 django.utils.autoreload C:\Users\2001k\Downloads\Auto_Care_App-master\Auto_Care_App-master\auto_care_backend\apps\locations\api\serializers.py changed, reloading.
[INFO] 2025-10-14 12:13:29,743 django.utils.autoreload Watching for file changes with StatReloader
[INFO] 2025-10-14 12:13:33,783 django.utils.autoreload C:\Users\2001k\Downloads\Auto_Care_App-master\Auto_Care_App-master\auto_care_backend\apps\locations\api\serializers.py changed, reloading.
[INFO] 2025-10-14 12:13:35,163 django.utils.autoreload Watching for file changes with StatReloader
[INFO] 2025-10-14 12:13:45,469 django.utils.autoreload C:\Users\2001k\Downloads\Auto_Care_App-master\Auto_Care_App-master\auto_care_backend\apps\locations\api\serializers.py changed, reloading.
[INFO] 2025-10-14 12:13:47,186 django.utils.autoreload Watching for file changes with StatReloader
[INFO] 2025-10-14 12:16:27,439 django.utils.autoreload Watching for file changes with StatReloader
[INFO] 2025-10-14 12:18:04,019 django.server "OPTIONS /api/accounts/send-otp/ HTTP/1.1" 200 0
[INFO] 2025-10-14 12:18:04,039 apps.accounts.api.views OTP request received from IP: 10.219.56.214
[INFO] 2025-10-14 12:18:04,301 apps.accounts.api.views OTP generated for 8999513014: 527547
[INFO] 2025-10-14 12:18:04,346 django.server "POST /api/accounts/send-otp/ HTTP/1.1" 200 64
[INFO] 2025-10-14 12:18:16,926 django.server "OPTIONS /api/accounts/verify-otp/ HTTP/1.1" 200 0
[INFO] 2025-10-14 12:18:17,084 apps.accounts.api.views Successful login for 8999513014 (New user: False)
[INFO] 2025-10-14 12:18:17,086 django.server "POST /api/accounts/verify-otp/ HTTP/1.1" 200 570
[INFO] 2025-10-14 12:18:17,420 django.server "OPTIONS /api/bookings/ HTTP/1.1" 200 0
[INFO] 2025-10-14 12:18:17,516 apps.bookings.api.views Bookings listed for user 8999513014: 0 bookings
[INFO] 2025-10-14 12:18:17,521 django.server "GET /api/bookings/ HTTP/1.1" 200 2
[INFO] 2025-10-14 12:18:24,339 django.server "OPTIONS /api/locations/addresses/ HTTP/1.1" 200 0
[INFO] 2025-10-14 12:18:24,557 django.server "GET /api/locations/addresses/ HTTP/1.1" 200 52
[INFO] 2025-10-14 12:18:35,703 django.server "POST /api/locations/addresses/ HTTP/1.1" 201 242
[INFO] 2025-10-14 12:18:35,850 django.server "GET /api/locations/addresses/ HTTP/1.1" 200 294
[INFO] 2025-10-14 12:18:42,251 django.server "GET /api/locations/addresses/ HTTP/1.1" 200 294
[INFO] 2025-10-14 12:19:52,677 django.server "GET /api/locations/addresses/ HTTP/1.1" 200 294
[INFO] 2025-10-14 12:38:47,838 django.utils.autoreload Watching for file changes with StatReloader
[INFO] 2025-10-14 12:39:43,590 django.server "OPTIONS /api/accounts/send-otp/ HTTP/1.1" 200 0
[INFO] 2025-10-14 12:39:43,655 apps.accounts.api.views OTP request received from IP: 10.219.56.214
[INFO] 2025-10-14 12:39:43,932 apps.accounts.api.views OTP generated for 8999513014: 042631
[INFO] 2025-10-14 12:39:43,937 django.server "POST /api/accounts/send-otp/ HTTP/1.1" 200 64
[INFO] 2025-10-14 12:39:54,722 django.server "OPTIONS /api/accounts/verify-otp/ HTTP/1.1" 200 0
[INFO] 2025-10-14 12:39:54,977 apps.accounts.api.views Successful login for 8999513014 (New user: False)
[INFO] 2025-10-14 12:39:54,979 django.server "POST /api/accounts/verify-otp/ HTTP/1.1" 200 570
[INFO] 2025-10-14 12:39:55,243 django.server "OPTIONS /api/bookings/ HTTP/1.1" 200 0
[INFO] 2025-10-14 12:39:55,382 apps.bookings.api.views Bookings listed for user 8999513014: 0 bookings
[INFO] 2025-10-14 12:39:55,392 django.server "GET /api/bookings/ HTTP/1.1" 200 2
[INFO] 2025-10-14 12:40:00,635 django.server "OPTIONS /api/locations/addresses/ HTTP/1.1" 200 0
[INFO] 2025-10-14 12:40:00,770 django.server "GET /api/locations/addresses/ HTTP/1.1" 200 294
[INFO] 2025-10-14 12:40:15,966 django.server "POST /api/locations/addresses/ HTTP/1.1" 201 244
[INFO] 2025-10-14 12:40:16,190 django.server "GET /api/locations/addresses/ HTTP/1.1" 200 540
[INFO] 2025-10-14 12:40:23,479 django.server "GET /api/locations/addresses/ HTTP/1.1" 200 540
[INFO] 2025-10-14 12:40:40,690 django.server "GET /api/locations/addresses/ HTTP/1.1" 200 540
[WARNING] 2025-10-14 12:44:54,345 django.request Unauthorized: /api/locations/addresses/
[WARNING] 2025-10-14 12:44:54,361 django.server "GET /api/locations/addresses/ HTTP/1.1" 401 172
[INFO] 2025-10-14 12:44:55,617 django.server "POST /api/accounts/token/refresh/ HTTP/1.1" 200 489
[INFO] 2025-10-14 12:44:56,691 django.server "GET /api/locations/addresses/ HTTP/1.1" 200 540
[INFO] 2025-10-14 12:55:44,470 django.utils.autoreload Watching for file changes with StatReloader
[INFO] 2025-10-14 12:57:08,334 django.server "OPTIONS /api/accounts/send-otp/ HTTP/1.1" 200 0
[INFO] 2025-10-14 12:57:08,742 apps.accounts.api.views OTP request received from IP: 10.219.56.214
[INFO] 2025-10-14 12:57:10,194 apps.accounts.api.views OTP generated for 8999513014: 535618
[INFO] 2025-10-14 12:57:10,402 django.server "POST /api/accounts/send-otp/ HTTP/1.1" 200 64
[INFO] 2025-10-14 12:57:18,154 django.server "OPTIONS /api/accounts/verify-otp/ HTTP/1.1" 200 0
[INFO] 2025-10-14 12:57:19,183 apps.accounts.api.views Successful login for 8999513014 (New user: False)
[INFO] 2025-10-14 12:57:19,189 django.server "POST /api/accounts/verify-otp/ HTTP/1.1" 200 570
[INFO] 2025-10-14 12:57:19,694 django.server "OPTIONS /api/bookings/ HTTP/1.1" 200 0
[INFO] 2025-10-14 12:57:19,960 apps.bookings.api.views Bookings listed for user 8999513014: 0 bookings
[INFO] 2025-10-14 12:57:19,987 django.server "GET /api/bookings/ HTTP/1.1" 200 2
[INFO] 2025-10-14 12:57:26,732 django.server "OPTIONS /api/locations/addresses/ HTTP/1.1" 200 0
[INFO] 2025-10-14 12:57:27,189 django.server "GET /api/locations/addresses/ HTTP/1.1" 200 540
[INFO] 2025-10-14 12:57:45,618 django.server "POST /api/locations/addresses/ HTTP/1.1" 201 243
[INFO] 2025-10-14 12:57:46,490 django.server "GET /api/locations/addresses/ HTTP/1.1" 200 785
[INFO] 2025-10-14 12:58:06,948 django.server "GET /api/locations/addresses/ HTTP/1.1" 200 785
[INFO] 2025-10-14 13:00:25,599 apps.accounts.api.views Profile fetched for 8999513014
[INFO] 2025-10-14 13:00:25,657 django.server "GET /api/accounts/profile/ HTTP/1.1" 200 60
[INFO] 2025-10-14 13:00:25,675 apps.bookings.api.views Bookings listed for user 8999513014: 0 bookings
[INFO] 2025-10-14 13:00:25,682 django.server "GET /api/bookings/ HTTP/1.1" 200 2
[INFO] 2025-10-14 13:00:40,065 django.server "GET /api/locations/addresses/ HTTP/1.1" 200 785
[INFO] 2025-10-14 14:58:16,208 django.utils.autoreload Watching for file changes with StatReloader
[INFO] 2025-10-14 15:07:26,631 django.server "OPTIONS /api/accounts/send-otp/ HTTP/1.1" 200 0
[INFO] 2025-10-14 15:07:26,760 apps.accounts.api.views OTP request received from IP: 10.219.56.214
[INFO] 2025-10-14 15:07:27,726 apps.accounts.api.views OTP generated for 8999513014: 638743
[INFO] 2025-10-14 15:07:27,743 django.server "POST /api/accounts/send-otp/ HTTP/1.1" 200 64
[INFO] 2025-10-14 15:07:46,865 django.server "OPTIONS /api/accounts/verify-otp/ HTTP/1.1" 200 0
[INFO] 2025-10-14 15:07:47,256 apps.accounts.api.views Successful login for 8999513014 (New user: False)
[INFO] 2025-10-14 15:07:47,260 django.server "POST /api/accounts/verify-otp/ HTTP/1.1" 200 570
[INFO] 2025-10-14 15:07:47,670 django.server "OPTIONS /api/bookings/ HTTP/1.1" 200 0
[INFO] 2025-10-14 15:07:47,867 apps.bookings.api.views Bookings listed for user 8999513014: 0 bookings
[INFO] 2025-10-14 15:07:47,905 django.server "GET /api/bookings/ HTTP/1.1" 200 2
[INFO] 2025-10-14 15:07:54,523 django.server "OPTIONS /api/locations/addresses/ HTTP/1.1" 200 0
[INFO] 2025-10-14 15:07:54,780 django.server "GET /api/locations/addresses/ HTTP/1.1" 200 785
[INFO] 2025-10-14 15:08:21,333 django.server "POST /api/locations/addresses/ HTTP/1.1" 201 257
[INFO] 2025-10-14 15:08:21,686 django.server "GET /api/locations/addresses/ HTTP/1.1" 200 1044
[INFO] 2025-10-14 15:21:35,105 django.utils.autoreload Watching for file changes with StatReloader
[INFO] 2025-10-14 15:37:06,578 django.server "OPTIONS /api/accounts/send-otp/ HTTP/1.1" 200 0
[INFO] 2025-10-14 15:37:06,710 apps.accounts.api.views OTP request received from IP: 10.219.56.214
[INFO] 2025-10-14 15:37:07,176 apps.accounts.api.views OTP generated for 8999513014: 048187
[INFO] 2025-10-14 15:37:07,184 django.server "POST /api/accounts/send-otp/ HTTP/1.1" 200 64
[INFO] 2025-10-14 15:37:20,037 django.server "OPTIONS /api/accounts/verify-otp/ HTTP/1.1" 200 0
[INFO] 2025-10-14 15:37:20,349 apps.accounts.api.views Successful login for 8999513014 (New user: False)
[INFO] 2025-10-14 15:37:20,354 django.server "POST /api/accounts/verify-otp/ HTTP/1.1" 200 570
[INFO] 2025-10-14 15:37:20,752 django.server "OPTIONS /api/bookings/ HTTP/1.1" 200 0
[INFO] 2025-10-14 15:37:21,194 apps.bookings.api.views Bookings listed for user 8999513014: 0 bookings
[INFO] 2025-10-14 15:37:21,208 django.server "GET /api/bookings/ HTTP/1.1" 200 2
[INFO] 2025-10-14 15:37:27,933 django.server "OPTIONS /api/locations/addresses/ HTTP/1.1" 200 0
[INFO] 2025-10-14 15:37:28,154 django.server "GET /api/locations/addresses/ HTTP/1.1" 200 1044
[INFO] 2025-10-14 15:37:33,067 django.server "GET /api/locations/addresses/ HTTP/1.1" 200 1044
[INFO] 2025-10-14 15:37:39,134 django.server "GET /api/locations/addresses/ HTTP/1.1" 200 1044
[WARNING] 2025-10-14 15:37:53,757 apps.bookings.api.views Booking creation failed for 8999513014: {'service_address': [ErrorDetail(string='This field is required.', code='required')]}
[WARNING] 2025-10-14 15:37:53,771 django.request Bad Request: /api/bookings/
[WARNING] 2025-10-14 15:37:53,777 django.server "POST /api/bookings/ HTTP/1.1" 400 47
[WARNING] 2025-10-14 15:38:11,558 apps.bookings.api.views Booking creation failed for 8999513014: {'service_address': [ErrorDetail(string='This field is required.', code='required')]}
[WARNING] 2025-10-14 15:38:11,561 django.request Bad Request: /api/bookings/
[WARNING] 2025-10-14 15:38:11,571 django.server "POST /api/bookings/ HTTP/1.1" 400 47
[INFO] 2025-10-14 15:38:16,749 django.server "GET /api/locations/addresses/ HTTP/1.1" 200 1044
[WARNING] 2025-10-14 15:38:19,432 apps.bookings.api.views Booking creation failed for 8999513014: {'service_address': [ErrorDetail(string='This field is required.', code='required')]}
[WARNING] 2025-10-14 15:38:19,436 django.request Bad Request: /api/bookings/
[WARNING] 2025-10-14 15:38:19,438 django.server "POST /api/bookings/ HTTP/1.1" 400 47
[INFO] 2025-10-14 15:38:21,424 django.server "GET /api/locations/addresses/ HTTP/1.1" 200 1044
[WARNING] 2025-10-14 15:38:23,810 apps.bookings.api.views Booking creation failed for 8999513014: {'service_address': [ErrorDetail(string='This field is required.', code='required')]}
[WARNING] 2025-10-14 15:38:23,818 django.request Bad Request: /api/bookings/
[WARNING] 2025-10-14 15:38:23,824 django.server "POST /api/bookings/ HTTP/1.1" 400 47
[INFO] 2025-10-14 15:56:20,507 django.utils.autoreload Watching for file changes with StatReloader
[INFO] 2025-10-14 15:57:15,944 django.server "OPTIONS /api/accounts/send-otp/ HTTP/1.1" 200 0
[INFO] 2025-10-14 15:57:15,958 apps.accounts.api.views OTP request received from IP: 10.219.56.214
[INFO] 2025-10-14 15:57:16,145 apps.accounts.api.views OTP generated for 8999513014: 880137
[INFO] 2025-10-14 15:57:16,147 django.server "POST /api/accounts/send-otp/ HTTP/1.1" 200 64
[INFO] 2025-10-14 15:57:23,644 django.server "OPTIONS /api/accounts/verify-otp/ HTTP/1.1" 200 0
[INFO] 2025-10-14 15:57:23,934 apps.accounts.api.views Successful login for 8999513014 (New user: False)
[INFO] 2025-10-14 15:57:23,945 django.server "POST /api/accounts/verify-otp/ HTTP/1.1" 200 570
[INFO] 2025-10-14 15:57:24,220 django.server "OPTIONS /api/bookings/ HTTP/1.1" 200 0
[INFO] 2025-10-14 15:57:24,312 apps.bookings.api.views Bookings listed for user 8999513014: 0 bookings
[INFO] 2025-10-14 15:57:24,315 django.server "GET /api/bookings/ HTTP/1.1" 200 2
[INFO] 2025-10-14 15:57:32,599 django.server "OPTIONS /api/locations/addresses/ HTTP/1.1" 200 0
[INFO] 2025-10-14 15:57:32,699 django.server "GET /api/locations/addresses/ HTTP/1.1" 200 1044
[INFO] 2025-10-14 15:57:44,073 django.server "GET /api/locations/addresses/ HTTP/1.1" 200 1044
[INFO] 2025-10-14 15:57:45,364 django.server "GET /api/locations/addresses/ HTTP/1.1" 200 1044
[INFO] 2025-10-14 16:01:32,405 django.utils.autoreload Watching for file changes with StatReloader
[INFO] 2025-10-14 16:05:39,998 django.server "OPTIONS /api/accounts/send-otp/ HTTP/1.1" 200 0
[INFO] 2025-10-14 16:05:40,010 apps.accounts.api.views OTP request received from IP: 10.219.56.214
[INFO] 2025-10-14 16:05:40,175 apps.accounts.api.views OTP generated for 8999513014: 640912
[INFO] 2025-10-14 16:05:40,178 django.server "POST /api/accounts/send-otp/ HTTP/1.1" 200 64
[INFO] 2025-10-14 16:05:53,514 django.server "OPTIONS /api/accounts/verify-otp/ HTTP/1.1" 200 0
[INFO] 2025-10-14 16:05:53,707 apps.accounts.api.views Successful login for 8999513014 (New user: False)
[INFO] 2025-10-14 16:05:53,710 django.server "POST /api/accounts/verify-otp/ HTTP/1.1" 200 570
[INFO] 2025-10-14 16:05:54,009 django.server "OPTIONS /api/bookings/ HTTP/1.1" 200 0
[INFO] 2025-10-14 16:05:54,100 apps.bookings.api.views Bookings listed for user 8999513014: 0 bookings
[INFO] 2025-10-14 16:05:54,107 django.server "GET /api/bookings/ HTTP/1.1" 200 2
[INFO] 2025-10-14 16:06:00,618 django.server "OPTIONS /api/locations/addresses/ HTTP/1.1" 200 0
[INFO] 2025-10-14 16:06:00,770 django.server "GET /api/locations/addresses/ HTTP/1.1" 200 1044
[INFO] 2025-10-14 16:06:14,923 django.server "GET /api/locations/addresses/ HTTP/1.1" 200 1044
[WARNING] 2025-10-14 16:06:15,109 apps.bookings.api.views Booking creation failed for 8999513014: {'location': [ErrorDetail(string='GPS coordinates (latitude and longitude) are required.', code='invalid')]}
[WARNING] 2025-10-14 16:06:15,115 django.request Bad Request: /api/bookings/
[WARNING] 2025-10-14 16:06:15,120 django.server "POST /api/bookings/ HTTP/1.1" 400 71
[INFO] 2025-10-14 17:46:36,777 django.utils.autoreload Watching for file changes with StatReloader
[INFO] 2025-10-14 17:50:20,886 django.utils.autoreload Watching for file changes with StatReloader
[INFO] 2025-10-14 17:52:48,600 django.server "OPTIONS /api/accounts/send-otp/ HTTP/1.1" 200 0
[INFO] 2025-10-14 17:52:48,853 apps.accounts.api.views OTP request received from IP: 10.219.56.214
[INFO] 2025-10-14 17:52:49,877 apps.accounts.api.views New user created: 9112666031
[INFO] 2025-10-14 17:52:49,916 apps.accounts.api.views OTP generated for 9112666031: 047689
[INFO] 2025-10-14 17:52:49,966 django.server "POST /api/accounts/send-otp/ HTTP/1.1" 200 64
[INFO] 2025-10-14 17:52:58,347 django.server "OPTIONS /api/accounts/verify-otp/ HTTP/1.1" 200 0
[INFO] 2025-10-14 17:53:00,312 apps.accounts.api.views Successful login for 9112666031 (New user: False)
[INFO] 2025-10-14 17:53:00,339 django.server "POST /api/accounts/verify-otp/ HTTP/1.1" 200 570
[INFO] 2025-10-14 17:53:00,794 django.server "OPTIONS /api/bookings/ HTTP/1.1" 200 0
[INFO] 2025-10-14 17:53:01,103 apps.bookings.api.views Bookings listed for user 9112666031: 0 bookings
[INFO] 2025-10-14 17:53:01,129 django.server "GET /api/bookings/ HTTP/1.1" 200 2
[INFO] 2025-10-14 17:53:09,587 django.server "OPTIONS /api/locations/addresses/ HTTP/1.1" 200 0
[INFO] 2025-10-14 17:53:11,770 django.server "GET /api/locations/addresses/ HTTP/1.1" 200 52
[INFO] 2025-10-14 17:53:38,577 django.server "POST /api/locations/addresses/ HTTP/1.1" 201 263
[INFO] 2025-10-14 17:53:40,502 django.server "GET /api/locations/addresses/ HTTP/1.1" 200 315
[INFO] 2025-10-14 17:53:57,066 django.server "GET /api/locations/addresses/ HTTP/1.1" 200 315
[WARNING] 2025-10-14 17:53:58,231 apps.bookings.api.views Booking creation failed for 9112666031: {'location': [ErrorDetail(string='GPS coordinates (latitude and longitude) are required.', code='invalid')]}
[WARNING] 2025-10-14 17:53:58,474 django.request Bad Request: /api/bookings/
[WARNING] 2025-10-14 17:53:58,525 django.server "POST /api/bookings/ HTTP/1.1" 400 71
[WARNING] 2025-10-14 21:05:36,637 django.request Not Found: /
[WARNING] 2025-10-14 21:05:36,644 django.server "GET / HTTP/1.1" 404 2633
[WARNING] 2025-10-14 21:05:58,297 django.request Not Found: /
[INFO] 2025-10-14 21:05:58,300 django.server - Broken pipe from ('10.219.56.214', 61233)
[WARNING] 2025-10-14 21:05:58,311 django.request Not Found: /loginMsg.js
[WARNING] 2025-10-14 21:05:58,312 django.server "GET /loginMsg.js HTTP/1.1" 404 2679
[WARNING] 2025-10-14 21:05:58,320 django.request Not Found: /cgi/get.cgi
[WARNING] 2025-10-14 21:05:58,321 django.server "GET /cgi/get.cgi?cmd=home_login HTTP/1.1" 404 2694
[INFO] 2025-10-14 21:11:33,855 django.utils.autoreload C:\Users\2001k\Downloads\Auto_Care_App-master\Auto_Care_App-master\auto_care_backend\apps\locations\api\serializers.py changed, reloading.
[INFO] 2025-10-14 21:11:36,547 django.utils.autoreload Watching for file changes with StatReloader
[INFO] 2025-10-14 21:13:20,259 django.utils.autoreload C:\Users\2001k\Downloads\Auto_Care_App-master\Auto_Care_App-master\auto_care_backend\apps\accounts\api\serializers.py changed, reloading.
[INFO] 2025-10-14 21:13:22,157 django.utils.autoreload Watching for file changes with StatReloader
[INFO] 2025-10-14 21:13:37,932 django.utils.autoreload C:\Users\2001k\Downloads\Auto_Care_App-master\Auto_Care_App-master\auto_care_backend\apps\accounts\api\serializers.py changed, reloading.
[INFO] 2025-10-14 21:13:38,933 django.utils.autoreload Watching for file changes with StatReloader
[INFO] 2025-10-14 21:14:13,216 django.utils.autoreload Watching for file changes with StatReloader
[INFO] 2025-10-14 21:17:55,889 django.utils.autoreload C:\Users\2001k\Downloads\Auto_Care_App-master\Auto_Care_App-master\auto_care_backend\apps\locations\api\views.py changed, reloading.
[INFO] 2025-10-14 21:17:59,687 django.utils.autoreload Watching for file changes with StatReloader
[INFO] 2025-10-14 21:19:08,759 django.utils.autoreload C:\Users\2001k\Downloads\Auto_Care_App-master\Auto_Care_App-master\auto_care_backend\apps\accounts\api\views.py changed, reloading.
[INFO] 2025-10-14 21:19:11,919 django.utils.autoreload Watching for file changes with StatReloader
[INFO] 2025-10-14 21:19:21,087 django.utils.autoreload C:\Users\2001k\Downloads\Auto_Care_App-master\Auto_Care_App-master\auto_care_backend\apps\accounts\api\views.py changed, reloading.
[INFO] 2025-10-14 21:19:23,170 django.utils.autoreload Watching for file changes with StatReloader
[INFO] 2025-10-14 21:20:10,609 django.utils.autoreload C:\Users\2001k\Downloads\Auto_Care_App-master\Auto_Care_App-master\auto_care_backend\apps\accounts\api\views.py changed, reloading.
[INFO] 2025-10-14 21:20:11,727 django.utils.autoreload Watching for file changes with StatReloader
[INFO] 2025-10-14 21:20:29,579 django.utils.autoreload Watching for file changes with StatReloader
[INFO] 2025-10-14 21:34:11,026 django.utils.autoreload Watching for file changes with StatReloader
[INFO] 2025-10-14 21:35:27,067 django.server "OPTIONS /api/accounts/send-otp/ HTTP/1.1" 200 0
[INFO] 2025-10-14 21:35:27,096 apps.accounts.api.views OTP request received from IP: 10.219.56.214
[INFO] 2025-10-14 21:35:27,503 apps.accounts.api.views OTP generated for 9112666031: 511955
[INFO] 2025-10-14 21:35:27,513 django.server "POST /api/accounts/send-otp/ HTTP/1.1" 200 64
[INFO] 2025-10-14 21:35:37,772 django.server "OPTIONS /api/accounts/verify-otp/ HTTP/1.1" 200 0
[INFO] 2025-10-14 21:35:38,093 apps.accounts.api.views Successful login for 9112666031 (New user: False)
[INFO] 2025-10-14 21:35:38,097 django.server "POST /api/accounts/verify-otp/ HTTP/1.1" 200 570
[INFO] 2025-10-14 21:35:38,443 django.server "OPTIONS /api/bookings/ HTTP/1.1" 200 0
[INFO] 2025-10-14 21:35:38,564 apps.bookings.api.views Bookings listed for user 9112666031: 0 bookings
[INFO] 2025-10-14 21:35:38,569 django.server "GET /api/bookings/ HTTP/1.1" 200 2
[INFO] 2025-10-14 21:35:49,631 django.server "OPTIONS /api/locations/addresses/ HTTP/1.1" 200 0
[ERROR] 2025-10-14 21:35:49,909 django.request Internal Server Error: /api/locations/addresses/
Traceback (most recent call last):
  File "C:\Users\2001k\AppData\Local\Programs\Python\Python313\Lib\site-packages\django\core\handlers\exception.py", line 55, in inner
    response = get_response(request)
  File "C:\Users\2001k\AppData\Local\Programs\Python\Python313\Lib\site-packages\django\core\handlers\base.py", line 197, in _get_response
    response = wrapped_callback(request, *callback_args, **callback_kwargs)
  File "C:\Users\2001k\AppData\Local\Programs\Python\Python313\Lib\site-packages\django\views\decorators\csrf.py", line 65, in _view_wrapper
    return view_func(request, *args, **kwargs)
  File "C:\Users\2001k\AppData\Local\Programs\Python\Python313\Lib\site-packages\django\views\generic\base.py", line 105, in view
    return self.dispatch(request, *args, **kwargs)
           ~~~~~~~~~~~~~^^^^^^^^^^^^^^^^^^^^^^^^^^
  File "C:\Users\2001k\AppData\Local\Programs\Python\Python313\Lib\site-packages\rest_framework\views.py", line 515, in dispatch
    response = self.handle_exception(exc)
  File "C:\Users\2001k\AppData\Local\Programs\Python\Python313\Lib\site-packages\rest_framework\views.py", line 475, in handle_exception
    self.raise_uncaught_exception(exc)
    ~~~~~~~~~~~~~~~~~~~~~~~~~~~~~^^^^^
  File "C:\Users\2001k\AppData\Local\Programs\Python\Python313\Lib\site-packages\rest_framework\views.py", line 486, in raise_uncaught_exception
    raise exc
  File "C:\Users\2001k\AppData\Local\Programs\Python\Python313\Lib\site-packages\rest_framework\views.py", line 512, in dispatch
    response = handler(request, *args, **kwargs)
  File "C:\Users\2001k\AppData\Local\Programs\Python\Python313\Lib\site-packages\rest_framework\generics.py", line 243, in get
    return self.list(request, *args, **kwargs)
           ~~~~~~~~~^^^^^^^^^^^^^^^^^^^^^^^^^^
  File "C:\Users\2001k\AppData\Local\Programs\Python\Python313\Lib\site-packages\rest_framework\mixins.py", line 43, in list
    return self.get_paginated_response(serializer.data)
                                       ^^^^^^^^^^^^^^^
  File "C:\Users\2001k\AppData\Local\Programs\Python\Python313\Lib\site-packages\rest_framework\serializers.py", line 797, in data
    ret = super().data
          ^^^^^^^^^^^^
  File "C:\Users\2001k\AppData\Local\Programs\Python\Python313\Lib\site-packages\rest_framework\serializers.py", line 251, in data
    self._data = self.to_representation(self.instance)
                 ~~~~~~~~~~~~~~~~~~~~~~^^^^^^^^^^^^^^^
  File "C:\Users\2001k\AppData\Local\Programs\Python\Python313\Lib\site-packages\rest_framework\serializers.py", line 716, in to_representation
    self.child.to_representation(item) for item in iterable
    ~~~~~~~~~~~~~~~~~~~~~~~~~~~~^^^^^^
  File "C:\Users\2001k\AppData\Local\Programs\Python\Python313\Lib\site-packages\rest_framework\serializers.py", line 525, in to_representation
    for field in fields:
                 ^^^^^^
  File "C:\Users\2001k\AppData\Local\Programs\Python\Python313\Lib\site-packages\rest_framework\serializers.py", line 386, in _readable_fields
    for field in self.fields.values():
                 ^^^^^^^^^^^
  File "C:\Users\2001k\AppData\Local\Programs\Python\Python313\Lib\site-packages\django\utils\functional.py", line 47, in __get__
    res = instance.__dict__[self.name] = self.func(instance)
                                         ~~~~~~~~~^^^^^^^^^^
  File "C:\Users\2001k\AppData\Local\Programs\Python\Python313\Lib\site-packages\rest_framework\serializers.py", line 374, in fields
    for key, value in self.get_fields().items():
                      ~~~~~~~~~~~~~~~^^
  File "C:\Users\2001k\AppData\Local\Programs\Python\Python313\Lib\site-packages\rest_framework\serializers.py", line 1105, in get_fields
    field_class, field_kwargs = self.build_field(
                                ~~~~~~~~~~~~~~~~^
        source, info, model, depth
        ^^^^^^^^^^^^^^^^^^^^^^^^^^
    )
    ^
  File "C:\Users\2001k\AppData\Local\Programs\Python\Python313\Lib\site-packages\rest_framework\serializers.py", line 1251, in build_field
    return self.build_unknown_field(field_name, model_class)
           ~~~~~~~~~~~~~~~~~~~~~~~~^^^^^^^^^^^^^^^^^^^^^^^^^
  File "C:\Users\2001k\AppData\Local\Programs\Python\Python313\Lib\site-packages\rest_framework\serializers.py", line 1369, in build_unknown_field
    raise ImproperlyConfigured(
    ...<2 lines>...
    )
django.core.exceptions.ImproperlyConfigured: Field name `updated_at` is not valid for model `Address` in `apps.locations.api.serializers.AddressSerializer`.
[ERROR] 2025-10-14 21:35:49,933 django.server "GET /api/locations/addresses/ HTTP/1.1" 500 158799
[ERROR] 2025-10-14 21:36:12,223 django.request Internal Server Error: /api/locations/addresses/
Traceback (most recent call last):
  File "C:\Users\2001k\AppData\Local\Programs\Python\Python313\Lib\site-packages\django\core\handlers\exception.py", line 55, in inner
    response = get_response(request)
  File "C:\Users\2001k\AppData\Local\Programs\Python\Python313\Lib\site-packages\django\core\handlers\base.py", line 197, in _get_response
    response = wrapped_callback(request, *callback_args, **callback_kwargs)
  File "C:\Users\2001k\AppData\Local\Programs\Python\Python313\Lib\site-packages\django\views\decorators\csrf.py", line 65, in _view_wrapper
    return view_func(request, *args, **kwargs)
  File "C:\Users\2001k\AppData\Local\Programs\Python\Python313\Lib\site-packages\django\views\generic\base.py", line 105, in view
    return self.dispatch(request, *args, **kwargs)
           ~~~~~~~~~~~~~^^^^^^^^^^^^^^^^^^^^^^^^^^
  File "C:\Users\2001k\AppData\Local\Programs\Python\Python313\Lib\site-packages\rest_framework\views.py", line 515, in dispatch
    response = self.handle_exception(exc)
  File "C:\Users\2001k\AppData\Local\Programs\Python\Python313\Lib\site-packages\rest_framework\views.py", line 475, in handle_exception
    self.raise_uncaught_exception(exc)
    ~~~~~~~~~~~~~~~~~~~~~~~~~~~~~^^^^^
  File "C:\Users\2001k\AppData\Local\Programs\Python\Python313\Lib\site-packages\rest_framework\views.py", line 486, in raise_uncaught_exception
    raise exc
  File "C:\Users\2001k\AppData\Local\Programs\Python\Python313\Lib\site-packages\rest_framework\views.py", line 512, in dispatch
    response = handler(request, *args, **kwargs)
  File "C:\Users\2001k\AppData\Local\Programs\Python\Python313\Lib\site-packages\rest_framework\generics.py", line 246, in post
    return self.create(request, *args, **kwargs)
           ~~~~~~~~~~~^^^^^^^^^^^^^^^^^^^^^^^^^^
  File "C:\Users\2001k\AppData\Local\Programs\Python\Python313\Lib\site-packages\rest_framework\mixins.py", line 18, in create
    serializer.is_valid(raise_exception=True)
    ~~~~~~~~~~~~~~~~~~~^^^^^^^^^^^^^^^^^^^^^^
  File "C:\Users\2001k\AppData\Local\Programs\Python\Python313\Lib\site-packages\rest_framework\serializers.py", line 225, in is_valid
    self._validated_data = self.run_validation(self.initial_data)
                           ~~~~~~~~~~~~~~~~~~~^^^^^^^^^^^^^^^^^^^
  File "C:\Users\2001k\AppData\Local\Programs\Python\Python313\Lib\site-packages\rest_framework\serializers.py", line 444, in run_validation
    value = self.to_internal_value(data)
  File "C:\Users\2001k\AppData\Local\Programs\Python\Python313\Lib\site-packages\rest_framework\serializers.py", line 497, in to_internal_value
    for field in fields:
                 ^^^^^^
  File "C:\Users\2001k\AppData\Local\Programs\Python\Python313\Lib\site-packages\rest_framework\serializers.py", line 380, in _writable_fields
    for field in self.fields.values():
                 ^^^^^^^^^^^
  File "C:\Users\2001k\AppData\Local\Programs\Python\Python313\Lib\site-packages\django\utils\functional.py", line 47, in __get__
    res = instance.__dict__[self.name] = self.func(instance)
                                         ~~~~~~~~~^^^^^^^^^^
  File "C:\Users\2001k\AppData\Local\Programs\Python\Python313\Lib\site-packages\rest_framework\serializers.py", line 374, in fields
    for key, value in self.get_fields().items():
                      ~~~~~~~~~~~~~~~^^
  File "C:\Users\2001k\AppData\Local\Programs\Python\Python313\Lib\site-packages\rest_framework\serializers.py", line 1105, in get_fields
    field_class, field_kwargs = self.build_field(
                                ~~~~~~~~~~~~~~~~^
        source, info, model, depth
        ^^^^^^^^^^^^^^^^^^^^^^^^^^
    )
    ^
  File "C:\Users\2001k\AppData\Local\Programs\Python\Python313\Lib\site-packages\rest_framework\serializers.py", line 1251, in build_field
    return self.build_unknown_field(field_name, model_class)
           ~~~~~~~~~~~~~~~~~~~~~~~~^^^^^^^^^^^^^^^^^^^^^^^^^
  File "C:\Users\2001k\AppData\Local\Programs\Python\Python313\Lib\site-packages\rest_framework\serializers.py", line 1369, in build_unknown_field
    raise ImproperlyConfigured(
    ...<2 lines>...
    )
django.core.exceptions.ImproperlyConfigured: Field name `updated_at` is not valid for model `Address` in `apps.locations.api.serializers.AddressSerializer`.
[ERROR] 2025-10-14 21:36:12,245 django.server "POST /api/locations/addresses/ HTTP/1.1" 500 155650
[ERROR] 2025-10-14 21:36:18,895 django.request Internal Server Error: /api/locations/addresses/
Traceback (most recent call last):
  File "C:\Users\2001k\AppData\Local\Programs\Python\Python313\Lib\site-packages\django\core\handlers\exception.py", line 55, in inner
    response = get_response(request)
  File "C:\Users\2001k\AppData\Local\Programs\Python\Python313\Lib\site-packages\django\core\handlers\base.py", line 197, in _get_response
    response = wrapped_callback(request, *callback_args, **callback_kwargs)
  File "C:\Users\2001k\AppData\Local\Programs\Python\Python313\Lib\site-packages\django\views\decorators\csrf.py", line 65, in _view_wrapper
    return view_func(request, *args, **kwargs)
  File "C:\Users\2001k\AppData\Local\Programs\Python\Python313\Lib\site-packages\django\views\generic\base.py", line 105, in view
    return self.dispatch(request, *args, **kwargs)
           ~~~~~~~~~~~~~^^^^^^^^^^^^^^^^^^^^^^^^^^
  File "C:\Users\2001k\AppData\Local\Programs\Python\Python313\Lib\site-packages\rest_framework\views.py", line 515, in dispatch
    response = self.handle_exception(exc)
  File "C:\Users\2001k\AppData\Local\Programs\Python\Python313\Lib\site-packages\rest_framework\views.py", line 475, in handle_exception
    self.raise_uncaught_exception(exc)
    ~~~~~~~~~~~~~~~~~~~~~~~~~~~~~^^^^^
  File "C:\Users\2001k\AppData\Local\Programs\Python\Python313\Lib\site-packages\rest_framework\views.py", line 486, in raise_uncaught_exception
    raise exc
  File "C:\Users\2001k\AppData\Local\Programs\Python\Python313\Lib\site-packages\rest_framework\views.py", line 512, in dispatch
    response = handler(request, *args, **kwargs)
  File "C:\Users\2001k\AppData\Local\Programs\Python\Python313\Lib\site-packages\rest_framework\generics.py", line 246, in post
    return self.create(request, *args, **kwargs)
           ~~~~~~~~~~~^^^^^^^^^^^^^^^^^^^^^^^^^^
  File "C:\Users\2001k\AppData\Local\Programs\Python\Python313\Lib\site-packages\rest_framework\mixins.py", line 18, in create
    serializer.is_valid(raise_exception=True)
    ~~~~~~~~~~~~~~~~~~~^^^^^^^^^^^^^^^^^^^^^^
  File "C:\Users\2001k\AppData\Local\Programs\Python\Python313\Lib\site-packages\rest_framework\serializers.py", line 225, in is_valid
    self._validated_data = self.run_validation(self.initial_data)
                           ~~~~~~~~~~~~~~~~~~~^^^^^^^^^^^^^^^^^^^
  File "C:\Users\2001k\AppData\Local\Programs\Python\Python313\Lib\site-packages\rest_framework\serializers.py", line 444, in run_validation
    value = self.to_internal_value(data)
  File "C:\Users\2001k\AppData\Local\Programs\Python\Python313\Lib\site-packages\rest_framework\serializers.py", line 497, in to_internal_value
    for field in fields:
                 ^^^^^^
  File "C:\Users\2001k\AppData\Local\Programs\Python\Python313\Lib\site-packages\rest_framework\serializers.py", line 380, in _writable_fields
    for field in self.fields.values():
                 ^^^^^^^^^^^
  File "C:\Users\2001k\AppData\Local\Programs\Python\Python313\Lib\site-packages\django\utils\functional.py", line 47, in __get__
    res = instance.__dict__[self.name] = self.func(instance)
                                         ~~~~~~~~~^^^^^^^^^^
  File "C:\Users\2001k\AppData\Local\Programs\Python\Python313\Lib\site-packages\rest_framework\serializers.py", line 374, in fields
    for key, value in self.get_fields().items():
                      ~~~~~~~~~~~~~~~^^
  File "C:\Users\2001k\AppData\Local\Programs\Python\Python313\Lib\site-packages\rest_framework\serializers.py", line 1105, in get_fields
    field_class, field_kwargs = self.build_field(
                                ~~~~~~~~~~~~~~~~^
        source, info, model, depth
        ^^^^^^^^^^^^^^^^^^^^^^^^^^
    )
    ^
  File "C:\Users\2001k\AppData\Local\Programs\Python\Python313\Lib\site-packages\rest_framework\serializers.py", line 1251, in build_field
    return self.build_unknown_field(field_name, model_class)
           ~~~~~~~~~~~~~~~~~~~~~~~~^^^^^^^^^^^^^^^^^^^^^^^^^
  File "C:\Users\2001k\AppData\Local\Programs\Python\Python313\Lib\site-packages\rest_framework\serializers.py", line 1369, in build_unknown_field
    raise ImproperlyConfigured(
    ...<2 lines>...
    )
django.core.exceptions.ImproperlyConfigured: Field name `updated_at` is not valid for model `Address` in `apps.locations.api.serializers.AddressSerializer`.
[ERROR] 2025-10-14 21:36:18,900 django.server "POST /api/locations/addresses/ HTTP/1.1" 500 155650
[INFO] 2025-10-14 21:45:24,902 django.utils.autoreload Watching for file changes with StatReloader
[INFO] 2025-10-14 21:47:18,516 django.utils.autoreload Watching for file changes with StatReloader
[INFO] 2025-10-14 21:47:21,901 django.server "OPTIONS /api/accounts/send-otp/ HTTP/1.1" 200 0
[INFO] 2025-10-14 21:47:21,988 apps.accounts.api.views OTP request received from IP: 10.219.56.214
[INFO] 2025-10-14 21:47:22,220 apps.accounts.api.views OTP generated for 9112666031: 179878
[INFO] 2025-10-14 21:47:22,222 django.server "POST /api/accounts/send-otp/ HTTP/1.1" 200 64
[INFO] 2025-10-14 21:47:30,338 django.server "OPTIONS /api/accounts/verify-otp/ HTTP/1.1" 200 0
[INFO] 2025-10-14 21:47:30,621 apps.accounts.api.views Successful login for 9112666031 (New user: False)
[INFO] 2025-10-14 21:47:30,675 django.server "POST /api/accounts/verify-otp/ HTTP/1.1" 200 570
[INFO] 2025-10-14 21:47:31,049 django.server "OPTIONS /api/bookings/ HTTP/1.1" 200 0
[INFO] 2025-10-14 21:47:31,174 apps.bookings.api.views Bookings listed for user 9112666031: 0 bookings
[INFO] 2025-10-14 21:47:31,182 django.server "GET /api/bookings/ HTTP/1.1" 200 2
[INFO] 2025-10-14 21:47:38,574 django.server "OPTIONS /api/locations/addresses/ HTTP/1.1" 200 0
[INFO] 2025-10-14 21:47:38,687 django.server "GET /api/locations/addresses/ HTTP/1.1" 200 315
[INFO] 2025-10-14 21:47:47,679 django.server "GET /api/locations/addresses/ HTTP/1.1" 200 315
[WARNING] 2025-10-14 21:47:47,833 apps.bookings.api.views Booking creation failed for 9112666031: {'location': [ErrorDetail(string='GPS coordinates (latitude and longitude) are required.', code='invalid')]}
[WARNING] 2025-10-14 21:47:47,844 django.request Bad Request: /api/bookings/
[WARNING] 2025-10-14 21:47:47,845 django.server "POST /api/bookings/ HTTP/1.1" 400 71
[INFO] 2025-10-14 22:18:59,022 django.utils.autoreload C:\Users\2001k\Downloads\Auto_Care_App-master\Auto_Care_App-master\auto_care_backend\apps\bookings\api\serializers.py changed, reloading.
[INFO] 2025-10-14 22:19:01,548 django.utils.autoreload Watching for file changes with StatReloader
[INFO] 2025-10-14 22:19:19,510 django.utils.autoreload Watching for file changes with StatReloader
[INFO] 2025-10-14 22:20:29,422 django.server "OPTIONS /api/accounts/send-otp/ HTTP/1.1" 200 0
[INFO] 2025-10-14 22:20:29,473 apps.accounts.api.views OTP request received from IP: 10.219.56.214
[INFO] 2025-10-14 22:20:29,804 apps.accounts.api.views OTP generated for 9112666031: 359857
[INFO] 2025-10-14 22:20:29,814 django.server "POST /api/accounts/send-otp/ HTTP/1.1" 200 64
[INFO] 2025-10-14 22:20:41,333 django.server "OPTIONS /api/accounts/verify-otp/ HTTP/1.1" 200 0
[INFO] 2025-10-14 22:20:41,536 apps.accounts.api.views Successful login for 9112666031 (New user: False)
[INFO] 2025-10-14 22:20:41,538 django.server "POST /api/accounts/verify-otp/ HTTP/1.1" 200 570
[INFO] 2025-10-14 22:20:41,980 django.server "OPTIONS /api/bookings/ HTTP/1.1" 200 0
[INFO] 2025-10-14 22:20:42,170 apps.bookings.api.views Bookings listed for user 9112666031: 0 bookings
[INFO] 2025-10-14 22:20:42,177 django.server "GET /api/bookings/ HTTP/1.1" 200 2
[INFO] 2025-10-14 22:20:46,760 django.server "OPTIONS /api/locations/addresses/ HTTP/1.1" 200 0
[INFO] 2025-10-14 22:20:46,863 django.server "GET /api/locations/addresses/ HTTP/1.1" 200 315
[INFO] 2025-10-14 22:20:57,284 django.server "GET /api/locations/addresses/ HTTP/1.1" 200 315
[ERROR] 2025-10-14 22:20:57,583 django.request Internal Server Error: /api/bookings/
Traceback (most recent call last):
  File "C:\Users\2001k\AppData\Local\Programs\Python\Python313\Lib\site-packages\django\core\handlers\exception.py", line 55, in inner
    response = get_response(request)
  File "C:\Users\2001k\AppData\Local\Programs\Python\Python313\Lib\site-packages\django\core\handlers\base.py", line 197, in _get_response
    response = wrapped_callback(request, *callback_args, **callback_kwargs)
  File "C:\Users\2001k\AppData\Local\Programs\Python\Python313\Lib\site-packages\django\views\decorators\csrf.py", line 65, in _view_wrapper
    return view_func(request, *args, **kwargs)
  File "C:\Users\2001k\AppData\Local\Programs\Python\Python313\Lib\site-packages\django\views\generic\base.py", line 105, in view
    return self.dispatch(request, *args, **kwargs)
           ~~~~~~~~~~~~~^^^^^^^^^^^^^^^^^^^^^^^^^^
  File "C:\Users\2001k\AppData\Local\Programs\Python\Python313\Lib\site-packages\rest_framework\views.py", line 515, in dispatch
    response = self.handle_exception(exc)
  File "C:\Users\2001k\AppData\Local\Programs\Python\Python313\Lib\site-packages\rest_framework\views.py", line 475, in handle_exception
    self.raise_uncaught_exception(exc)
    ~~~~~~~~~~~~~~~~~~~~~~~~~~~~~^^^^^
  File "C:\Users\2001k\AppData\Local\Programs\Python\Python313\Lib\site-packages\rest_framework\views.py", line 486, in raise_uncaught_exception
    raise exc
  File "C:\Users\2001k\AppData\Local\Programs\Python\Python313\Lib\site-packages\rest_framework\views.py", line 512, in dispatch
    response = handler(request, *args, **kwargs)
  File "C:\Users\2001k\Downloads\Auto_Care_App-master\Auto_Care_App-master\auto_care_backend\apps\bookings\api\views.py", line 30, in post
    booking = serializer.save(user=request.user)
  File "C:\Users\2001k\AppData\Local\Programs\Python\Python313\Lib\site-packages\rest_framework\serializers.py", line 210, in save
    self.instance = self.create(validated_data)
                    ~~~~~~~~~~~^^^^^^^^^^^^^^^^
  File "C:\Users\2001k\Downloads\Auto_Care_App-master\Auto_Care_App-master\auto_care_backend\apps\bookings\api\serializers.py", line 163, in create
    booking = Booking.objects.create(user=user, **validated_data)
TypeError: django.db.models.query.QuerySet.create() got multiple values for keyword argument 'user'
[ERROR] 2025-10-14 22:20:57,595 django.server "POST /api/bookings/ HTTP/1.1" 500 116750
[INFO] 2025-10-14 22:54:59,844 django.utils.autoreload C:\Users\2001k\Downloads\Auto_Care_App-master\Auto_Care_App-master\auto_care_backend\apps\bookings\api\serializers.py changed, reloading.
[INFO] 2025-10-14 22:55:03,133 django.utils.autoreload Watching for file changes with StatReloader
[INFO] 2025-10-14 22:55:55,704 django.utils.autoreload C:\Users\2001k\Downloads\Auto_Care_App-master\Auto_Care_App-master\auto_care_backend\apps\bookings\api\serializers.py changed, reloading.
[INFO] 2025-10-14 22:55:56,803 django.utils.autoreload Watching for file changes with StatReloader
[INFO] 2025-10-14 22:56:12,508 django.utils.autoreload Watching for file changes with StatReloader
[INFO] 2025-10-14 22:57:20,799 django.server "OPTIONS /api/accounts/send-otp/ HTTP/1.1" 200 0
[INFO] 2025-10-14 22:57:20,812 apps.accounts.api.views OTP request received from IP: 10.219.56.214
[INFO] 2025-10-14 22:57:21,001 apps.accounts.api.views OTP generated for 9112666031: 462721
[INFO] 2025-10-14 22:57:21,003 django.server "POST /api/accounts/send-otp/ HTTP/1.1" 200 64
[INFO] 2025-10-14 22:57:29,511 django.server "OPTIONS /api/accounts/verify-otp/ HTTP/1.1" 200 0
[INFO] 2025-10-14 22:57:29,714 apps.accounts.api.views Successful login for 9112666031 (New user: False)
[INFO] 2025-10-14 22:57:29,717 django.server "POST /api/accounts/verify-otp/ HTTP/1.1" 200 570
[INFO] 2025-10-14 22:57:29,996 django.server "OPTIONS /api/bookings/ HTTP/1.1" 200 0
[INFO] 2025-10-14 22:57:30,111 apps.bookings.api.views Bookings listed for user 9112666031: 0 bookings
[INFO] 2025-10-14 22:57:30,116 django.server "GET /api/bookings/ HTTP/1.1" 200 2
[INFO] 2025-10-14 22:57:37,951 django.server "OPTIONS /api/locations/addresses/ HTTP/1.1" 200 0
[INFO] 2025-10-14 22:57:38,051 django.server "GET /api/locations/addresses/ HTTP/1.1" 200 315
[INFO] 2025-10-14 22:57:49,175 django.server "GET /api/locations/addresses/ HTTP/1.1" 200 315
[WARNING] 2025-10-14 22:57:49,379 apps.bookings.models Booking None created outside service area: None, None
[INFO] 2025-10-14 22:57:49,405 apps.bookings.api.views Booking created: 1 for user 9112666031
[INFO] 2025-10-14 22:57:49,414 django.server "POST /api/bookings/ HTTP/1.1" 201 365
[INFO] 2025-10-14 22:58:17,484 django.server "OPTIONS /api/accounts/profile/ HTTP/1.1" 200 0
[INFO] 2025-10-14 22:58:17,977 apps.bookings.api.views Bookings listed for user 9112666031: 1 bookings
[INFO] 2025-10-14 22:58:18,032 django.server "GET /api/bookings/ HTTP/1.1" 200 367
[INFO] 2025-10-14 22:58:18,073 apps.accounts.api.views Profile fetched for 9112666031
[INFO] 2025-10-14 22:58:18,141 django.server "GET /api/accounts/profile/ HTTP/1.1" 200 60
[INFO] 2025-10-14 22:58:18,318 apps.bookings.api.views Bookings listed for user 9112666031: 1 bookings
[INFO] 2025-10-14 22:58:18,330 django.server "GET /api/bookings/ HTTP/1.1" 200 367
[INFO] 2025-10-14 22:59:07,740 apps.bookings.api.views Bookings listed for user 9112666031: 1 bookings
[INFO] 2025-10-14 22:59:07,747 django.server "GET /api/bookings/ HTTP/1.1" 200 367
[INFO] 2025-10-14 22:59:12,256 django.server "GET /api/locations/addresses/ HTTP/1.1" 200 315
[INFO] 2025-10-14 22:59:31,822 django.server "OPTIONS /api/auth/logout/ HTTP/1.1" 200 0
[WARNING] 2025-10-14 22:59:31,883 django.request Not Found: /api/auth/logout/
[WARNING] 2025-10-14 22:59:31,885 django.server "POST /api/auth/logout/ HTTP/1.1" 404 2700
[INFO] 2025-10-14 22:59:40,258 apps.accounts.api.views OTP request received from IP: 10.219.56.214
[INFO] 2025-10-14 22:59:40,404 apps.accounts.api.views OTP generated for 8999513014: 645915
[INFO] 2025-10-14 22:59:40,408 django.server "POST /api/accounts/send-otp/ HTTP/1.1" 200 64
[INFO] 2025-10-14 22:59:50,841 apps.accounts.api.views Successful login for 8999513014 (New user: False)
[INFO] 2025-10-14 22:59:50,843 django.server "POST /api/accounts/verify-otp/ HTTP/1.1" 200 570
[INFO] 2025-10-14 22:59:51,104 apps.bookings.api.views Bookings listed for user 8999513014: 0 bookings
[INFO] 2025-10-14 22:59:51,106 django.server "GET /api/bookings/ HTTP/1.1" 200 2
[INFO] 2025-10-14 23:00:03,241 django.server "GET /api/locations/addresses/ HTTP/1.1" 200 1044
[INFO] 2025-10-14 23:00:13,037 django.server "GET /api/locations/addresses/ HTTP/1.1" 200 1044
[WARNING] 2025-10-14 23:00:13,205 apps.bookings.models Booking None created outside service area: None, None
[INFO] 2025-10-14 23:00:13,211 apps.bookings.api.views Booking created: 2 for user 8999513014
[INFO] 2025-10-14 23:00:13,217 django.server "POST /api/bookings/ HTTP/1.1" 201 364
[INFO] 2025-10-14 23:00:21,655 apps.bookings.api.views Bookings listed for user 8999513014: 1 bookings
[INFO] 2025-10-14 23:00:21,657 apps.accounts.api.views Profile fetched for 8999513014
[INFO] 2025-10-14 23:00:21,660 django.server "GET /api/accounts/profile/ HTTP/1.1" 200 60
[INFO] 2025-10-14 23:00:21,663 django.server "GET /api/bookings/ HTTP/1.1" 200 366
[INFO] 2025-10-14 23:00:21,775 apps.bookings.api.views Bookings listed for user 8999513014: 1 bookings
[INFO] 2025-10-14 23:00:21,781 django.server "GET /api/bookings/ HTTP/1.1" 200 366
[WARNING] 2025-10-14 23:00:36,660 django.request Not Found: /api/auth/logout/
[WARNING] 2025-10-14 23:00:36,664 django.server "POST /api/auth/logout/ HTTP/1.1" 404 2700
[INFO] 2025-10-14 23:01:01,731 apps.accounts.api.views OTP request received from IP: 10.219.56.214
[INFO] 2025-10-14 23:01:01,833 apps.accounts.api.views OTP generated for 9168238418: 177483
[INFO] 2025-10-14 23:01:01,835 django.server "POST /api/accounts/send-otp/ HTTP/1.1" 200 64
[INFO] 2025-10-14 23:01:09,753 apps.accounts.api.views Successful login for 9168238418 (New user: False)
[INFO] 2025-10-14 23:01:09,756 django.server "POST /api/accounts/verify-otp/ HTTP/1.1" 200 570
[INFO] 2025-10-14 23:01:10,027 apps.bookings.api.views Bookings listed for user 9168238418: 0 bookings
[INFO] 2025-10-14 23:01:10,030 django.server "GET /api/bookings/ HTTP/1.1" 200 2
[INFO] 2025-10-14 23:21:56,553 django.server "GET /api/locations/addresses/ HTTP/1.1" 200 52
[INFO] 2025-10-14 23:22:25,858 django.server "GET /api/locations/addresses/ HTTP/1.1" 200 52
[INFO] 2025-10-15 15:17:02,593 django.utils.autoreload Watching for file changes with StatReloader
[WARNING] 2025-10-15 15:38:30,408 django.request Not Found: /
[WARNING] 2025-10-15 15:38:30,430 django.server "GET / HTTP/1.1" 404 2632
[WARNING] 2025-10-15 15:38:41,058 django.request Not Found: /
[INFO] 2025-10-15 15:38:41,066 django.server - Broken pipe from ('192.168.1.46', 52686)
[WARNING] 2025-10-15 15:38:41,073 django.request Not Found: /loginMsg.js
[WARNING] 2025-10-15 15:38:41,075 django.server "GET /loginMsg.js HTTP/1.1" 404 2678
[WARNING] 2025-10-15 15:38:41,085 django.request Not Found: /cgi/get.cgi
[WARNING] 2025-10-15 15:38:41,086 django.server "GET /cgi/get.cgi?cmd=home_login HTTP/1.1" 404 2693
[INFO] 2025-10-15 19:47:36,293 django.utils.autoreload Watching for file changes with StatReloader
[WARNING] 2025-10-15 19:48:11,537 django.request Not Found: /
[WARNING] 2025-10-15 19:48:11,548 django.server "GET / HTTP/1.1" 404 2633
[WARNING] 2025-10-15 19:48:28,282 django.request Not Found: /
[INFO] 2025-10-15 19:48:28,301 django.server - Broken pipe from ('10.219.56.214', 57101)
[WARNING] 2025-10-15 19:48:28,334 django.request Not Found: /loginMsg.js
[WARNING] 2025-10-15 19:48:28,335 django.server "GET /loginMsg.js HTTP/1.1" 404 2679
[WARNING] 2025-10-15 19:48:28,358 django.request Not Found: /cgi/get.cgi
[WARNING] 2025-10-15 19:48:28,363 django.server "GET /cgi/get.cgi?cmd=home_login HTTP/1.1" 404 2694
[INFO] 2025-10-15 19:51:47,078 django.server "OPTIONS /api/accounts/send-otp/ HTTP/1.1" 200 0
[INFO] 2025-10-15 19:51:47,145 apps.accounts.api.views OTP request received from IP: 10.219.56.214
[INFO] 2025-10-15 19:51:47,669 apps.accounts.api.views New user created: 9921235894
[INFO] 2025-10-15 19:51:47,682 apps.accounts.api.views OTP generated for 9921235894: 870862
[INFO] 2025-10-15 19:51:47,725 django.server "POST /api/accounts/send-otp/ HTTP/1.1" 200 64
[INFO] 2025-10-15 19:52:02,130 django.server "OPTIONS /api/accounts/verify-otp/ HTTP/1.1" 200 0
[INFO] 2025-10-15 19:52:02,840 apps.accounts.api.views Successful login for 9921235894 (New user: False)
[INFO] 2025-10-15 19:52:02,841 django.server "POST /api/accounts/verify-otp/ HTTP/1.1" 200 570
[INFO] 2025-10-15 19:52:03,325 django.server "OPTIONS /api/bookings/ HTTP/1.1" 200 0
[INFO] 2025-10-15 19:52:03,451 apps.bookings.api.views Bookings listed for user 9921235894: 0 bookings
[INFO] 2025-10-15 19:52:03,459 django.server "GET /api/bookings/ HTTP/1.1" 200 2
[INFO] 2025-10-15 19:52:22,647 django.server "OPTIONS /api/locations/addresses/ HTTP/1.1" 200 0
[INFO] 2025-10-15 19:52:22,737 django.server "GET /api/locations/addresses/ HTTP/1.1" 200 52
[INFO] 2025-10-15 19:52:56,076 django.server "POST /api/locations/addresses/ HTTP/1.1" 201 270
[INFO] 2025-10-15 19:52:56,223 django.server "GET /api/locations/addresses/ HTTP/1.1" 200 322
[INFO] 2025-10-15 19:53:15,857 django.server "GET /api/locations/addresses/ HTTP/1.1" 200 322
[WARNING] 2025-10-15 19:53:16,215 apps.bookings.models Booking None created outside service area: None, None
[INFO] 2025-10-15 19:53:16,231 apps.bookings.api.views Booking created: 3 for user 9921235894
[INFO] 2025-10-15 19:53:16,246 django.server "POST /api/bookings/ HTTP/1.1" 201 368
[INFO] 2025-10-15 19:54:02,388 django.server "OPTIONS /api/accounts/profile/ HTTP/1.1" 200 0
[INFO] 2025-10-15 19:54:02,770 apps.accounts.api.views Profile fetched for 9921235894
[INFO] 2025-10-15 19:54:02,803 apps.bookings.api.views Bookings listed for user 9921235894: 1 bookings
[INFO] 2025-10-15 19:54:02,836 django.server "GET /api/accounts/profile/ HTTP/1.1" 200 60
[INFO] 2025-10-15 19:54:02,843 django.server "GET /api/bookings/ HTTP/1.1" 200 370
[INFO] 2025-10-15 19:54:03,004 apps.bookings.api.views Bookings listed for user 9921235894: 1 bookings
[INFO] 2025-10-15 19:54:03,015 django.server "GET /api/bookings/ HTTP/1.1" 200 370
[INFO] 2025-10-15 19:54:44,704 apps.bookings.api.views Bookings listed for user 9921235894: 1 bookings
[INFO] 2025-10-15 19:54:44,717 django.server "GET /api/bookings/ HTTP/1.1" 200 370
[INFO] 2025-10-15 19:54:59,334 django.server "GET /api/locations/addresses/ HTTP/1.1" 200 322
[INFO] 2025-10-15 19:55:02,011 apps.bookings.api.views Bookings listed for user 9921235894: 1 bookings
[INFO] 2025-10-15 19:55:02,019 django.server "GET /api/bookings/ HTTP/1.1" 200 370
[INFO] 2025-10-15 19:55:08,220 apps.accounts.api.views Profile fetched for 9921235894
[INFO] 2025-10-15 19:55:08,222 django.server "GET /api/accounts/profile/ HTTP/1.1" 200 60
[INFO] 2025-10-15 19:56:02,813 apps.accounts.api.views Profile updated for 9921235894
[INFO] 2025-10-15 19:56:02,816 django.server "PUT /api/accounts/profile/ HTTP/1.1" 200 90
[INFO] 2025-10-15 19:56:02,949 apps.accounts.api.views Profile fetched for 9921235894
[INFO] 2025-10-15 19:56:02,950 django.server "GET /api/accounts/profile/ HTTP/1.1" 200 90
[INFO] 2025-10-15 19:57:46,074 apps.bookings.api.views Bookings listed for user 9921235894: 1 bookings
[INFO] 2025-10-15 19:57:46,075 apps.accounts.api.views Profile fetched for 9921235894
[INFO] 2025-10-15 19:57:46,083 django.server "GET /api/accounts/profile/ HTTP/1.1" 200 90
[INFO] 2025-10-15 19:57:46,090 django.server "GET /api/bookings/ HTTP/1.1" 200 384
[INFO] 2025-10-15 20:59:06,409 django.utils.autoreload Watching for file changes with StatReloader
[INFO] 2025-10-15 21:01:02,960 django.server "OPTIONS /api/accounts/send-otp/ HTTP/1.1" 200 0
[INFO] 2025-10-15 21:01:02,982 apps.accounts.api.views OTP request received from IP: 10.219.56.214
[INFO] 2025-10-15 21:01:03,204 apps.accounts.api.views New user created: 912****4444
[INFO] 2025-10-15 21:01:03,214 apps.accounts.api.views OTP: ******
[INFO] 2025-10-15 21:01:03,219 django.server "POST /api/accounts/send-otp/ HTTP/1.1" 200 64
[INFO] 2025-10-15 21:01:16,408 django.server "OPTIONS /api/accounts/verify-otp/ HTTP/1.1" 200 0
[INFO] 2025-10-15 21:01:16,555 apps.accounts.api.views Successful login for 912****4444 (New user: False)
[INFO] 2025-10-15 21:01:16,556 django.server "POST /api/accounts/verify-otp/ HTTP/1.1" 200 570
[INFO] 2025-10-15 21:01:17,085 django.server "OPTIONS /api/bookings/ HTTP/1.1" 200 0
[INFO] 2025-10-15 21:01:17,204 apps.bookings.api.views Bookings listed for user 912****4444: 0 bookings
[INFO] 2025-10-15 21:01:17,209 django.server "GET /api/bookings/ HTTP/1.1" 200 2
[INFO] 2025-10-15 21:01:52,480 django.server "OPTIONS /api/locations/addresses/ HTTP/1.1" 200 0
[INFO] 2025-10-15 21:01:52,601 django.server "GET /api/locations/addresses/ HTTP/1.1" 200 52
[INFO] 2025-10-15 21:02:12,412 django.server "POST /api/locations/addresses/ HTTP/1.1" 201 249
[INFO] 2025-10-15 21:02:12,569 django.server "GET /api/locations/addresses/ HTTP/1.1" 200 301
[INFO] 2025-10-15 21:02:28,286 django.server "GET /api/locations/addresses/ HTTP/1.1" 200 301
[ERROR] 2025-10-15 21:02:28,694 django.request Internal Server Error: /api/bookings/
Traceback (most recent call last):
  File "C:\Users\2001k\AppData\Local\Programs\Python\Python313\Lib\site-packages\django\core\handlers\exception.py", line 55, in inner
    response = get_response(request)
  File "C:\Users\2001k\AppData\Local\Programs\Python\Python313\Lib\site-packages\django\core\handlers\base.py", line 197, in _get_response
    response = wrapped_callback(request, *callback_args, **callback_kwargs)
  File "C:\Users\2001k\AppData\Local\Programs\Python\Python313\Lib\site-packages\django\views\decorators\csrf.py", line 65, in _view_wrapper
    return view_func(request, *args, **kwargs)
  File "C:\Users\2001k\AppData\Local\Programs\Python\Python313\Lib\site-packages\django\views\generic\base.py", line 105, in view
    return self.dispatch(request, *args, **kwargs)
           ~~~~~~~~~~~~~^^^^^^^^^^^^^^^^^^^^^^^^^^
  File "C:\Users\2001k\AppData\Local\Programs\Python\Python313\Lib\site-packages\rest_framework\views.py", line 515, in dispatch
    response = self.handle_exception(exc)
  File "C:\Users\2001k\AppData\Local\Programs\Python\Python313\Lib\site-packages\rest_framework\views.py", line 475, in handle_exception
    self.raise_uncaught_exception(exc)
    ~~~~~~~~~~~~~~~~~~~~~~~~~~~~~^^^^^
  File "C:\Users\2001k\AppData\Local\Programs\Python\Python313\Lib\site-packages\rest_framework\views.py", line 486, in raise_uncaught_exception
    raise exc
  File "C:\Users\2001k\AppData\Local\Programs\Python\Python313\Lib\site-packages\rest_framework\views.py", line 512, in dispatch
    response = handler(request, *args, **kwargs)
  File "C:\Users\2001k\Downloads\Auto_Care_App-master\Auto_Care_App-master\auto_care_backend\apps\bookings\api\views.py", line 29, in post
    if serializer.is_valid():
       ~~~~~~~~~~~~~~~~~~~^^
  File "C:\Users\2001k\AppData\Local\Programs\Python\Python313\Lib\site-packages\rest_framework\serializers.py", line 225, in is_valid
    self._validated_data = self.run_validation(self.initial_data)
                           ~~~~~~~~~~~~~~~~~~~^^^^^^^^^^^^^^^^^^^
  File "C:\Users\2001k\AppData\Local\Programs\Python\Python313\Lib\site-packages\rest_framework\serializers.py", line 444, in run_validation
    value = self.to_internal_value(data)
  File "C:\Users\2001k\AppData\Local\Programs\Python\Python313\Lib\site-packages\rest_framework\serializers.py", line 497, in to_internal_value
    for field in fields:
                 ^^^^^^
  File "C:\Users\2001k\AppData\Local\Programs\Python\Python313\Lib\site-packages\rest_framework\serializers.py", line 380, in _writable_fields
    for field in self.fields.values():
                 ^^^^^^^^^^^
  File "C:\Users\2001k\AppData\Local\Programs\Python\Python313\Lib\site-packages\django\utils\functional.py", line 47, in __get__
    res = instance.__dict__[self.name] = self.func(instance)
                                         ~~~~~~~~~^^^^^^^^^^
  File "C:\Users\2001k\AppData\Local\Programs\Python\Python313\Lib\site-packages\rest_framework\serializers.py", line 374, in fields
    for key, value in self.get_fields().items():
                      ~~~~~~~~~~~~~~~^^
  File "C:\Users\2001k\AppData\Local\Programs\Python\Python313\Lib\site-packages\rest_framework\serializers.py", line 1105, in get_fields
    field_class, field_kwargs = self.build_field(
                                ~~~~~~~~~~~~~~~~^
        source, info, model, depth
        ^^^^^^^^^^^^^^^^^^^^^^^^^^
    )
    ^
  File "C:\Users\2001k\AppData\Local\Programs\Python\Python313\Lib\site-packages\rest_framework\serializers.py", line 1251, in build_field
    return self.build_unknown_field(field_name, model_class)
           ~~~~~~~~~~~~~~~~~~~~~~~~^^^^^^^^^^^^^^^^^^^^^^^^^
  File "C:\Users\2001k\AppData\Local\Programs\Python\Python313\Lib\site-packages\rest_framework\serializers.py", line 1369, in build_unknown_field
    raise ImproperlyConfigured(
    ...<2 lines>...
    )
django.core.exceptions.ImproperlyConfigured: Field name `service_address` is not valid for model `Booking` in `apps.bookings.api.serializers.BookingSerializer`.
[ERROR] 2025-10-15 21:02:28,718 django.server "POST /api/bookings/ HTTP/1.1" 500 151510
[INFO] 2025-10-15 21:03:49,035 django.utils.autoreload Watching for file changes with StatReloader
[INFO] 2025-10-15 21:05:15,378 django.server "OPTIONS /api/accounts/send-otp/ HTTP/1.1" 200 0
[INFO] 2025-10-15 21:05:15,517 apps.accounts.api.views OTP request received from IP: 10.219.56.214
[INFO] 2025-10-15 21:05:16,660 apps.accounts.api.views New user created: 9273728731
[INFO] 2025-10-15 21:05:16,681 apps.accounts.api.views OTP generated for 9273728731: 978192
[INFO] 2025-10-15 21:05:16,712 django.server "POST /api/accounts/send-otp/ HTTP/1.1" 200 64
[INFO] 2025-10-15 21:05:31,260 django.server "OPTIONS /api/accounts/verify-otp/ HTTP/1.1" 200 0
[INFO] 2025-10-15 21:05:31,450 apps.accounts.api.views Successful login for 9273728731 (New user: False)
[INFO] 2025-10-15 21:05:31,454 django.server "POST /api/accounts/verify-otp/ HTTP/1.1" 200 570
[INFO] 2025-10-15 21:05:31,808 django.server "OPTIONS /api/bookings/ HTTP/1.1" 200 0
[INFO] 2025-10-15 21:05:31,926 apps.bookings.api.views Bookings listed for user 9273728731: 0 bookings
[ERROR] 2025-10-15 21:05:32,152 django.request Internal Server Error: /api/bookings/
Traceback (most recent call last):
  File "C:\Users\2001k\AppData\Local\Programs\Python\Python313\Lib\site-packages\django\db\backends\utils.py", line 105, in _execute
    return self.cursor.execute(sql, params)
           ~~~~~~~~~~~~~~~~~~~^^^^^^^^^^^^^
psycopg2.errors.UndefinedColumn: column bookings_booking.service_address does not exist
LINE 1: ...king"."latitude", "bookings_booking"."longitude", "bookings_...
                                                             ^


The above exception was the direct cause of the following exception:

Traceback (most recent call last):
  File "C:\Users\2001k\AppData\Local\Programs\Python\Python313\Lib\site-packages\django\core\handlers\exception.py", line 55, in inner
    response = get_response(request)
  File "C:\Users\2001k\AppData\Local\Programs\Python\Python313\Lib\site-packages\django\core\handlers\base.py", line 197, in _get_response
    response = wrapped_callback(request, *callback_args, **callback_kwargs)
  File "C:\Users\2001k\AppData\Local\Programs\Python\Python313\Lib\site-packages\django\views\decorators\csrf.py", line 65, in _view_wrapper
    return view_func(request, *args, **kwargs)
  File "C:\Users\2001k\AppData\Local\Programs\Python\Python313\Lib\site-packages\django\views\generic\base.py", line 105, in view
    return self.dispatch(request, *args, **kwargs)
           ~~~~~~~~~~~~~^^^^^^^^^^^^^^^^^^^^^^^^^^
  File "C:\Users\2001k\AppData\Local\Programs\Python\Python313\Lib\site-packages\rest_framework\views.py", line 515, in dispatch
    response = self.handle_exception(exc)
  File "C:\Users\2001k\AppData\Local\Programs\Python\Python313\Lib\site-packages\rest_framework\views.py", line 475, in handle_exception
    self.raise_uncaught_exception(exc)
    ~~~~~~~~~~~~~~~~~~~~~~~~~~~~~^^^^^
  File "C:\Users\2001k\AppData\Local\Programs\Python\Python313\Lib\site-packages\rest_framework\views.py", line 486, in raise_uncaught_exception
    raise exc
  File "C:\Users\2001k\AppData\Local\Programs\Python\Python313\Lib\site-packages\rest_framework\views.py", line 512, in dispatch
    response = handler(request, *args, **kwargs)
  File "C:\Users\2001k\Downloads\Auto_Care_App-master\Auto_Care_App-master\auto_care_backend\apps\bookings\api\views.py", line 24, in get
    return Response(serializer.data if serializer.data else [], status=status.HTTP_200_OK)
                                       ^^^^^^^^^^^^^^^
  File "C:\Users\2001k\AppData\Local\Programs\Python\Python313\Lib\site-packages\rest_framework\serializers.py", line 797, in data
    ret = super().data
          ^^^^^^^^^^^^
  File "C:\Users\2001k\AppData\Local\Programs\Python\Python313\Lib\site-packages\rest_framework\serializers.py", line 251, in data
    self._data = self.to_representation(self.instance)
                 ~~~~~~~~~~~~~~~~~~~~~~^^^^^^^^^^^^^^^
  File "C:\Users\2001k\AppData\Local\Programs\Python\Python313\Lib\site-packages\rest_framework\serializers.py", line 716, in to_representation
    self.child.to_representation(item) for item in iterable
                                                   ^^^^^^^^
  File "C:\Users\2001k\AppData\Local\Programs\Python\Python313\Lib\site-packages\django\db\models\query.py", line 384, in __iter__
    self._fetch_all()
    ~~~~~~~~~~~~~~~^^
  File "C:\Users\2001k\AppData\Local\Programs\Python\Python313\Lib\site-packages\django\db\models\query.py", line 1949, in _fetch_all
    self._result_cache = list(self._iterable_class(self))
                         ~~~~^^^^^^^^^^^^^^^^^^^^^^^^^^^^
  File "C:\Users\2001k\AppData\Local\Programs\Python\Python313\Lib\site-packages\django\db\models\query.py", line 91, in __iter__
    results = compiler.execute_sql(
        chunked_fetch=self.chunked_fetch, chunk_size=self.chunk_size
    )
  File "C:\Users\2001k\AppData\Local\Programs\Python\Python313\Lib\site-packages\django\db\models\sql\compiler.py", line 1623, in execute_sql
    cursor.execute(sql, params)
    ~~~~~~~~~~~~~~^^^^^^^^^^^^^
  File "C:\Users\2001k\AppData\Local\Programs\Python\Python313\Lib\site-packages\django\db\backends\utils.py", line 122, in execute
    return super().execute(sql, params)
           ~~~~~~~~~~~~~~~^^^^^^^^^^^^^
  File "C:\Users\2001k\AppData\Local\Programs\Python\Python313\Lib\site-packages\django\db\backends\utils.py", line 79, in execute
    return self._execute_with_wrappers(
           ~~~~~~~~~~~~~~~~~~~~~~~~~~~^
        sql, params, many=False, executor=self._execute
        ^^^^^^^^^^^^^^^^^^^^^^^^^^^^^^^^^^^^^^^^^^^^^^^
    )
    ^
  File "C:\Users\2001k\AppData\Local\Programs\Python\Python313\Lib\site-packages\django\db\backends\utils.py", line 92, in _execute_with_wrappers
    return executor(sql, params, many, context)
  File "C:\Users\2001k\AppData\Local\Programs\Python\Python313\Lib\site-packages\django\db\backends\utils.py", line 100, in _execute
    with self.db.wrap_database_errors:
         ^^^^^^^^^^^^^^^^^^^^^^^^^^^^
  File "C:\Users\2001k\AppData\Local\Programs\Python\Python313\Lib\site-packages\django\db\utils.py", line 91, in __exit__
    raise dj_exc_value.with_traceback(traceback) from exc_value
  File "C:\Users\2001k\AppData\Local\Programs\Python\Python313\Lib\site-packages\django\db\backends\utils.py", line 105, in _execute
    return self.cursor.execute(sql, params)
           ~~~~~~~~~~~~~~~~~~~^^^^^^^^^^^^^
django.db.utils.ProgrammingError: column bookings_booking.service_address does not exist
LINE 1: ...king"."latitude", "bookings_booking"."longitude", "bookings_...
                                                             ^

[ERROR] 2025-10-15 21:05:32,184 django.server "GET /api/bookings/ HTTP/1.1" 500 175005
[INFO] 2025-10-15 21:19:14,441 django.utils.autoreload Watching for file changes with StatReloader
[INFO] 2025-10-15 21:21:15,272 django.server "OPTIONS /api/accounts/send-otp/ HTTP/1.1" 200 0
[INFO] 2025-10-15 21:21:15,462 apps.accounts.api.views OTP request received from IP: 10.219.56.214
[INFO] 2025-10-15 21:21:16,207 apps.accounts.api.views New user created: 8999513012
[INFO] 2025-10-15 21:21:16,254 apps.accounts.api.views OTP generated for 8999513012: 821841
[INFO] 2025-10-15 21:21:16,310 django.server "POST /api/accounts/send-otp/ HTTP/1.1" 200 64
[INFO] 2025-10-15 21:21:24,312 django.server "OPTIONS /api/accounts/verify-otp/ HTTP/1.1" 200 0
[INFO] 2025-10-15 21:21:24,615 apps.accounts.api.views Successful login for 8999513012 (New user: False)
[INFO] 2025-10-15 21:21:24,618 django.server "POST /api/accounts/verify-otp/ HTTP/1.1" 200 570
[INFO] 2025-10-15 21:21:25,084 django.server "OPTIONS /api/bookings/ HTTP/1.1" 200 0
[INFO] 2025-10-15 21:21:25,298 apps.bookings.api.views Bookings listed for user 8999513012: 0 bookings
[ERROR] 2025-10-15 21:21:25,594 django.request Internal Server Error: /api/bookings/
Traceback (most recent call last):
  File "C:\Users\2001k\AppData\Local\Programs\Python\Python313\Lib\site-packages\django\db\backends\utils.py", line 105, in _execute
    return self.cursor.execute(sql, params)
           ~~~~~~~~~~~~~~~~~~~^^^^^^^^^^^^^
psycopg2.errors.UndefinedColumn: column bookings_booking.service_address does not exist
LINE 1: ...king"."latitude", "bookings_booking"."longitude", "bookings_...
                                                             ^


The above exception was the direct cause of the following exception:

Traceback (most recent call last):
  File "C:\Users\2001k\AppData\Local\Programs\Python\Python313\Lib\site-packages\django\core\handlers\exception.py", line 55, in inner
    response = get_response(request)
  File "C:\Users\2001k\AppData\Local\Programs\Python\Python313\Lib\site-packages\django\core\handlers\base.py", line 197, in _get_response
    response = wrapped_callback(request, *callback_args, **callback_kwargs)
  File "C:\Users\2001k\AppData\Local\Programs\Python\Python313\Lib\site-packages\django\views\decorators\csrf.py", line 65, in _view_wrapper
    return view_func(request, *args, **kwargs)
  File "C:\Users\2001k\AppData\Local\Programs\Python\Python313\Lib\site-packages\django\views\generic\base.py", line 105, in view
    return self.dispatch(request, *args, **kwargs)
           ~~~~~~~~~~~~~^^^^^^^^^^^^^^^^^^^^^^^^^^
  File "C:\Users\2001k\AppData\Local\Programs\Python\Python313\Lib\site-packages\rest_framework\views.py", line 515, in dispatch
    response = self.handle_exception(exc)
  File "C:\Users\2001k\AppData\Local\Programs\Python\Python313\Lib\site-packages\rest_framework\views.py", line 475, in handle_exception
    self.raise_uncaught_exception(exc)
    ~~~~~~~~~~~~~~~~~~~~~~~~~~~~~^^^^^
  File "C:\Users\2001k\AppData\Local\Programs\Python\Python313\Lib\site-packages\rest_framework\views.py", line 486, in raise_uncaught_exception
    raise exc
  File "C:\Users\2001k\AppData\Local\Programs\Python\Python313\Lib\site-packages\rest_framework\views.py", line 512, in dispatch
    response = handler(request, *args, **kwargs)
  File "C:\Users\2001k\Downloads\Auto_Care_App-master\Auto_Care_App-master\auto_care_backend\apps\bookings\api\views.py", line 24, in get
    return Response(serializer.data if serializer.data else [], status=status.HTTP_200_OK)
                                       ^^^^^^^^^^^^^^^
  File "C:\Users\2001k\AppData\Local\Programs\Python\Python313\Lib\site-packages\rest_framework\serializers.py", line 797, in data
    ret = super().data
          ^^^^^^^^^^^^
  File "C:\Users\2001k\AppData\Local\Programs\Python\Python313\Lib\site-packages\rest_framework\serializers.py", line 251, in data
    self._data = self.to_representation(self.instance)
                 ~~~~~~~~~~~~~~~~~~~~~~^^^^^^^^^^^^^^^
  File "C:\Users\2001k\AppData\Local\Programs\Python\Python313\Lib\site-packages\rest_framework\serializers.py", line 716, in to_representation
    self.child.to_representation(item) for item in iterable
                                                   ^^^^^^^^
  File "C:\Users\2001k\AppData\Local\Programs\Python\Python313\Lib\site-packages\django\db\models\query.py", line 384, in __iter__
    self._fetch_all()
    ~~~~~~~~~~~~~~~^^
  File "C:\Users\2001k\AppData\Local\Programs\Python\Python313\Lib\site-packages\django\db\models\query.py", line 1949, in _fetch_all
    self._result_cache = list(self._iterable_class(self))
                         ~~~~^^^^^^^^^^^^^^^^^^^^^^^^^^^^
  File "C:\Users\2001k\AppData\Local\Programs\Python\Python313\Lib\site-packages\django\db\models\query.py", line 91, in __iter__
    results = compiler.execute_sql(
        chunked_fetch=self.chunked_fetch, chunk_size=self.chunk_size
    )
  File "C:\Users\2001k\AppData\Local\Programs\Python\Python313\Lib\site-packages\django\db\models\sql\compiler.py", line 1623, in execute_sql
    cursor.execute(sql, params)
    ~~~~~~~~~~~~~~^^^^^^^^^^^^^
  File "C:\Users\2001k\AppData\Local\Programs\Python\Python313\Lib\site-packages\django\db\backends\utils.py", line 122, in execute
    return super().execute(sql, params)
           ~~~~~~~~~~~~~~~^^^^^^^^^^^^^
  File "C:\Users\2001k\AppData\Local\Programs\Python\Python313\Lib\site-packages\django\db\backends\utils.py", line 79, in execute
    return self._execute_with_wrappers(
           ~~~~~~~~~~~~~~~~~~~~~~~~~~~^
        sql, params, many=False, executor=self._execute
        ^^^^^^^^^^^^^^^^^^^^^^^^^^^^^^^^^^^^^^^^^^^^^^^
    )
    ^
  File "C:\Users\2001k\AppData\Local\Programs\Python\Python313\Lib\site-packages\django\db\backends\utils.py", line 92, in _execute_with_wrappers
    return executor(sql, params, many, context)
  File "C:\Users\2001k\AppData\Local\Programs\Python\Python313\Lib\site-packages\django\db\backends\utils.py", line 100, in _execute
    with self.db.wrap_database_errors:
         ^^^^^^^^^^^^^^^^^^^^^^^^^^^^
  File "C:\Users\2001k\AppData\Local\Programs\Python\Python313\Lib\site-packages\django\db\utils.py", line 91, in __exit__
    raise dj_exc_value.with_traceback(traceback) from exc_value
  File "C:\Users\2001k\AppData\Local\Programs\Python\Python313\Lib\site-packages\django\db\backends\utils.py", line 105, in _execute
    return self.cursor.execute(sql, params)
           ~~~~~~~~~~~~~~~~~~~^^^^^^^^^^^^^
django.db.utils.ProgrammingError: column bookings_booking.service_address does not exist
LINE 1: ...king"."latitude", "bookings_booking"."longitude", "bookings_...
                                                             ^

[ERROR] 2025-10-15 21:21:25,645 django.server "GET /api/bookings/ HTTP/1.1" 500 175005
[INFO] 2025-10-15 21:21:52,204 django.server "OPTIONS /api/locations/addresses/ HTTP/1.1" 200 0
[INFO] 2025-10-15 21:21:52,384 django.server "GET /api/locations/addresses/ HTTP/1.1" 200 52
[INFO] 2025-10-15 21:22:05,119 django.server "POST /api/locations/addresses/ HTTP/1.1" 201 239
[INFO] 2025-10-15 21:22:05,388 django.server "GET /api/locations/addresses/ HTTP/1.1" 200 291
[INFO] 2025-10-15 21:22:15,692 django.server "GET /api/locations/addresses/ HTTP/1.1" 200 291
[WARNING] 2025-10-15 21:22:15,959 apps.bookings.models Booking None created outside service area: None, None
[ERROR] 2025-10-15 21:22:16,159 django.request Internal Server Error: /api/bookings/
Traceback (most recent call last):
  File "C:\Users\2001k\AppData\Local\Programs\Python\Python313\Lib\site-packages\django\db\backends\utils.py", line 105, in _execute
    return self.cursor.execute(sql, params)
           ~~~~~~~~~~~~~~~~~~~^^^^^^^^^^^^^
psycopg2.errors.UndefinedColumn: column "service_address" of relation "bookings_booking" does not exist
LINE 1: ..., "created_at", "notes", "latitude", "longitude", "service_a...
                                                             ^


The above exception was the direct cause of the following exception:

Traceback (most recent call last):
  File "C:\Users\2001k\AppData\Local\Programs\Python\Python313\Lib\site-packages\django\core\handlers\exception.py", line 55, in inner
    response = get_response(request)
  File "C:\Users\2001k\AppData\Local\Programs\Python\Python313\Lib\site-packages\django\core\handlers\base.py", line 197, in _get_response
    response = wrapped_callback(request, *callback_args, **callback_kwargs)
  File "C:\Users\2001k\AppData\Local\Programs\Python\Python313\Lib\site-packages\django\views\decorators\csrf.py", line 65, in _view_wrapper
    return view_func(request, *args, **kwargs)
  File "C:\Users\2001k\AppData\Local\Programs\Python\Python313\Lib\site-packages\django\views\generic\base.py", line 105, in view
    return self.dispatch(request, *args, **kwargs)
           ~~~~~~~~~~~~~^^^^^^^^^^^^^^^^^^^^^^^^^^
  File "C:\Users\2001k\AppData\Local\Programs\Python\Python313\Lib\site-packages\rest_framework\views.py", line 515, in dispatch
    response = self.handle_exception(exc)
  File "C:\Users\2001k\AppData\Local\Programs\Python\Python313\Lib\site-packages\rest_framework\views.py", line 475, in handle_exception
    self.raise_uncaught_exception(exc)
    ~~~~~~~~~~~~~~~~~~~~~~~~~~~~~^^^^^
  File "C:\Users\2001k\AppData\Local\Programs\Python\Python313\Lib\site-packages\rest_framework\views.py", line 486, in raise_uncaught_exception
    raise exc
  File "C:\Users\2001k\AppData\Local\Programs\Python\Python313\Lib\site-packages\rest_framework\views.py", line 512, in dispatch
    response = handler(request, *args, **kwargs)
  File "C:\Users\2001k\Downloads\Auto_Care_App-master\Auto_Care_App-master\auto_care_backend\apps\bookings\api\views.py", line 30, in post
    booking = serializer.save(user=request.user)
  File "C:\Users\2001k\AppData\Local\Programs\Python\Python313\Lib\site-packages\rest_framework\serializers.py", line 210, in save
    self.instance = self.create(validated_data)
                    ~~~~~~~~~~~^^^^^^^^^^^^^^^^
  File "C:\Users\2001k\AppData\Local\Programs\Python\Python313\Lib\site-packages\rest_framework\serializers.py", line 991, in create
    instance = ModelClass._default_manager.create(**validated_data)
  File "C:\Users\2001k\AppData\Local\Programs\Python\Python313\Lib\site-packages\django\db\models\manager.py", line 87, in manager_method
    return getattr(self.get_queryset(), name)(*args, **kwargs)
           ~~~~~~~~~~~~~~~~~~~~~~~~~~~~~~~~~~^^^^^^^^^^^^^^^^^
  File "C:\Users\2001k\AppData\Local\Programs\Python\Python313\Lib\site-packages\django\db\models\query.py", line 663, in create
    obj.save(force_insert=True, using=self.db)
    ~~~~~~~~^^^^^^^^^^^^^^^^^^^^^^^^^^^^^^^^^^
  File "C:\Users\2001k\Downloads\Auto_Care_App-master\Auto_Care_App-master\auto_care_backend\apps\bookings\models.py", line 147, in save
    super().save(*args, **kwargs)
    ~~~~~~~~~~~~^^^^^^^^^^^^^^^^^
  File "C:\Users\2001k\AppData\Local\Programs\Python\Python313\Lib\site-packages\django\db\models\base.py", line 902, in save
    self.save_base(
    ~~~~~~~~~~~~~~^
        using=using,
        ^^^^^^^^^^^^
    ...<2 lines>...
        update_fields=update_fields,
        ^^^^^^^^^^^^^^^^^^^^^^^^^^^^
    )
    ^
  File "C:\Users\2001k\AppData\Local\Programs\Python\Python313\Lib\site-packages\django\db\models\base.py", line 1008, in save_base
    updated = self._save_table(
        raw,
    ...<4 lines>...
        update_fields,
    )
  File "C:\Users\2001k\AppData\Local\Programs\Python\Python313\Lib\site-packages\django\db\models\base.py", line 1169, in _save_table
    results = self._do_insert(
        cls._base_manager, using, fields, returning_fields, raw
    )
  File "C:\Users\2001k\AppData\Local\Programs\Python\Python313\Lib\site-packages\django\db\models\base.py", line 1210, in _do_insert
    return manager._insert(
           ~~~~~~~~~~~~~~~^
        [self],
        ^^^^^^^
    ...<3 lines>...
        raw=raw,
        ^^^^^^^^
    )
    ^
  File "C:\Users\2001k\AppData\Local\Programs\Python\Python313\Lib\site-packages\django\db\models\manager.py", line 87, in manager_method
    return getattr(self.get_queryset(), name)(*args, **kwargs)
           ~~~~~~~~~~~~~~~~~~~~~~~~~~~~~~~~~~^^^^^^^^^^^^^^^^^
  File "C:\Users\2001k\AppData\Local\Programs\Python\Python313\Lib\site-packages\django\db\models\query.py", line 1868, in _insert
    return query.get_compiler(using=using).execute_sql(returning_fields)
           ~~~~~~~~~~~~~~~~~~~~~~~~~~~~~~~~~~~~~~~~~~~^^^^^^^^^^^^^^^^^^
  File "C:\Users\2001k\AppData\Local\Programs\Python\Python313\Lib\site-packages\django\db\models\sql\compiler.py", line 1882, in execute_sql
    cursor.execute(sql, params)
    ~~~~~~~~~~~~~~^^^^^^^^^^^^^
  File "C:\Users\2001k\AppData\Local\Programs\Python\Python313\Lib\site-packages\django\db\backends\utils.py", line 122, in execute
    return super().execute(sql, params)
           ~~~~~~~~~~~~~~~^^^^^^^^^^^^^
  File "C:\Users\2001k\AppData\Local\Programs\Python\Python313\Lib\site-packages\django\db\backends\utils.py", line 79, in execute
    return self._execute_with_wrappers(
           ~~~~~~~~~~~~~~~~~~~~~~~~~~~^
        sql, params, many=False, executor=self._execute
        ^^^^^^^^^^^^^^^^^^^^^^^^^^^^^^^^^^^^^^^^^^^^^^^
    )
    ^
  File "C:\Users\2001k\AppData\Local\Programs\Python\Python313\Lib\site-packages\django\db\backends\utils.py", line 92, in _execute_with_wrappers
    return executor(sql, params, many, context)
  File "C:\Users\2001k\AppData\Local\Programs\Python\Python313\Lib\site-packages\django\db\backends\utils.py", line 100, in _execute
    with self.db.wrap_database_errors:
         ^^^^^^^^^^^^^^^^^^^^^^^^^^^^
  File "C:\Users\2001k\AppData\Local\Programs\Python\Python313\Lib\site-packages\django\db\utils.py", line 91, in __exit__
    raise dj_exc_value.with_traceback(traceback) from exc_value
  File "C:\Users\2001k\AppData\Local\Programs\Python\Python313\Lib\site-packages\django\db\backends\utils.py", line 105, in _execute
    return self.cursor.execute(sql, params)
           ~~~~~~~~~~~~~~~~~~~^^^^^^^^^^^^^
django.db.utils.ProgrammingError: column "service_address" of relation "bookings_booking" does not exist
LINE 1: ..., "created_at", "notes", "latitude", "longitude", "service_a...
                                                             ^

[ERROR] 2025-10-15 21:22:16,186 django.server "POST /api/bookings/ HTTP/1.1" 500 213375
[INFO] 2025-10-15 22:21:35,591 django.utils.autoreload Watching for file changes with StatReloader
[INFO] 2025-10-15 22:22:56,923 django.server "OPTIONS /api/accounts/send-otp/ HTTP/1.1" 200 0
[INFO] 2025-10-15 22:22:57,001 apps.accounts.api.views OTP request received from IP: 10.219.56.214
[INFO] 2025-10-15 22:22:57,325 apps.accounts.api.views New user created: 8999513013
[INFO] 2025-10-15 22:22:57,341 apps.accounts.api.views OTP generated for 8999513013: 126972
[INFO] 2025-10-15 22:22:57,408 django.server "POST /api/accounts/send-otp/ HTTP/1.1" 200 64
[INFO] 2025-10-15 22:23:06,349 django.server "OPTIONS /api/accounts/verify-otp/ HTTP/1.1" 200 0
[INFO] 2025-10-15 22:23:06,618 apps.accounts.api.views Successful login for 8999513013 (New user: False)
[INFO] 2025-10-15 22:23:06,620 django.server "POST /api/accounts/verify-otp/ HTTP/1.1" 200 570
[INFO] 2025-10-15 22:23:06,888 django.server "OPTIONS /api/bookings/ HTTP/1.1" 200 0
[INFO] 2025-10-15 22:23:06,978 apps.bookings.api.views Bookings listed for user 8999513013: 0 bookings
[INFO] 2025-10-15 22:23:06,983 django.server "GET /api/bookings/ HTTP/1.1" 200 2
[INFO] 2025-10-15 22:23:32,096 django.server "OPTIONS /api/locations/addresses/ HTTP/1.1" 200 0
[INFO] 2025-10-15 22:23:32,201 django.server "GET /api/locations/addresses/ HTTP/1.1" 200 52
[INFO] 2025-10-15 22:23:45,562 django.server "POST /api/locations/addresses/ HTTP/1.1" 201 245
[INFO] 2025-10-15 22:23:45,812 django.server "GET /api/locations/addresses/ HTTP/1.1" 200 297
[INFO] 2025-10-15 22:23:56,805 django.server "GET /api/locations/addresses/ HTTP/1.1" 200 297
[INFO] 2025-10-15 22:23:56,978 apps.bookings.api.serializers Booking created: ID 1 for user 8999513013
[INFO] 2025-10-15 22:23:56,978 apps.bookings.api.views Booking created: 1 for user 8999513013
[INFO] 2025-10-15 22:23:56,980 django.server "POST /api/bookings/ HTTP/1.1" 201 381
[INFO] 2025-10-15 23:01:28,509 django.utils.autoreload Watching for file changes with StatReloader
